Workbook

Sheet README
A1: CTDI k-factors are used by RTI Piranha and RTI Ocean software to calculate CTDI(vol) from measurements of CTDI100(center).
A2: k = CTDIw/CTDI100(center)
A3: k-factors for some common scanners are built into RTI Ocean, but for newer scanners that aren't on the list, need to either select a similar scanner or use an appropriate k-factor.
A4: See RTI Application Note AN-40
A6: Spreadsheet tabs contain k-factors derived from Siemens Dosimetry and Imaging performance reports for the scanner.

Sheet Sheet9
A1: Scanner | B1: kV | C1: Coll NxT | D1: Width (mm) | E1: Acq NxT | F1: k (16 cm) | G1: k (32 cm) | I1: Naeotom Alpha | J1: 1 | M1: Siemens | N1: 1
A2: Confidence 64 | B2: 70 | C2: 2x1 | D2: 2 | E2: 2x1 | F2: 1.0699301 | G2: 1.741379 | I2: Definition AS | J2: 2 | M2: Neurologica | N2: 2
A3: Confidence 64 | B3: 70 | C3: 1x5 | D3: 5 | E3: 1x5 | F3: 1.0661479 | G3: 1.75 | I3: Somatom Flash A tube | J3: 3
A4: Confidence 64 | B4: 70 | C4: 10x0.6 | D4: 6 | E4: 20x0.6 | F4: 1.0645161 | G4: 1.724638 | I4: Somatom Force | J4: 4
A5: Confidence 64 | B5: 70 | C5: 6x1.2 | D5: 7.2 | E5: 6x1.2 | F5: 1.0677507 | G5: 1.733333 | I5: Somatom Drive | J5: 5
A6: Confidence 64 | B6: 70 | C6: 1x10 | D6: 10 | E6: 1x10 | F6: 1.0661479 | G6: 1.75 | I6: Definition Edge | J6: 6
A7: Confidence 64 | B7: 70 | C7: 20x0.6 | D7: 12 | E7: 40x0.6 | F7: 1.0632184 | G7: 1.742857 | I7: go.Top | J7: 7
A8: Confidence 64 | B8: 70 | C8: 12x1.2 | D8: 14.4 | E8: 12x1.2 | F8: 1.0699088 | G8: 1.731343 | I8: Confidence 64 | J8: 8
A9: Confidence 64 | B9: 70 | C9: 32x0.6 | D9: 19.2 | E9: 64x0.6 | F9: 1.0617284 | G9: 1.712121 | I9: Confidence 20 | J9: 9
A10: Confidence 64 | B10: 70 | C10: 16x1.2 | D10: 19.2 | E10: 16x1.2 | F10: 1.0698413 | G10: 1.734375 | I10: X.cite | J10: 10
A11: Confidence 64 | B11: 80 | C11: 2x1 | D11: 2 | E11: 2x1 | F11: 1.0437637 | G11: 1.61165 | I11: Biograph Vision | J11: 11
A12: Confidence 64 | B12: 80 | C12: 1x5 | D12: 5 | E12: 1x5 | F12: 1.0439024 | G12: 1.619565 | I12: Intevo Bold | J12: 12
A13: Confidence 64 | B13: 80 | C13: 10x0.6 | D13: 6 | E13: 20x0.6 | F13: 1.0422794 | G13: 1.606557 | I13: Symbia Pro.specta | J13: 13
A14: Confidence 64 | B14: 80 | C14: 6x1.2 | D14: 7.2 | E14: 6x1.2 | F14: 1.0458404 | G14: 1.609023 | I14: Pro.Pulse A tube | J14: 14
... A17: Confidence 64 | B17: 80 | C17: 12x1.2 | D17: 14.4 | E17: 12x1.2 | F17: 1.0457143 | G17: 1.618644 | I17: Somatom Flash B tube | J17: 17
A18: Confidence 64 | B18: 80 | C18: 32x0.6 | D18: 19.2 | E18: 64x0.6 | F18: 1.040619 | G18: 1.603448
A19: Confidence 64 | B19: 80 | C19: 16x1.2 | D19: 19.2 | E19: 16x1.2 | F19: 1.0457257 | G19: 1.619469
A20: Confidence 64 | B20: 100 | C20: 2x1 | D20: 2 | E20: 2x1 | F20: 1.020362 | G20: 1.488889
A21: Confidence 64 | B21: 100 | C21: 1x5 | D21: 5 | E21: 1x5 | F21: 1.0214376 | G21: 1.490099
A22: Confidence 64 | B22: 100 | C22: 10x0.6 | D22: 6 | E22: 20x0.6 | F22: 1.0161444 | G22: 1.479401
A23: Confidence 64 | B23: 100 | C23: 6x1.2 | D23: 7.2 | E23: 6x1.2 | F23: 1.0210526 | G23: 1.489655
A24: Confidence 64 | B24: 100 | C24: 1x10 | D24: 10 | E24: 1x10 | F24: 1.0214376 | G24: 1.490099
A25: Confidence 64 | B25: 100 | C25: 20x0.6 | D25: 12 | E25: 40x0.6 | F25: 1.0167754 | G25: 1.481618
A26: Confidence 64 | B26: 100 | C26: 12x1.2 | D26: 14.4 | E26: 12x1.2 | F26: 1.0216322 | G26: 1.490347
A27: Confidence 64 | B27: 100 | C27: 32x0.6 | D27: 19.2 | E27: 64x0.6 | F27: 1.016 | G27: 1.476378
A28: Confidence 64 | B28: 100 | C28: 16x1.2 | D28: 19.2 | E28: 16x1.2 | F28: 1.0215827 | G28: 1.493927
A29: Confidence 64 | B29: 120 | C29: 2x1 | D29: 2 | E29: 2x1 | F29: 1.0120886 | G29: 1.432763
... A86: Confidence 20 | B86: 140 | C86: 16x1.2 | D86: 19.2 | E86: 16x1.2 | F86: 1.0072743 | G86: 1.538259
A87: go.Top | B87: 70 | C87: 6x0.6 | D87: 3.6 | E87: 6x0.6
A88: go.Top | B88: 70 | C88: 1x5 | D88: 5 | E88: 1x5 | F88: 1.0810811 | G88: 1.888889
A89: go.Top | B89: 70 | C89: 1x10 | D89: 10 | E89: 1x10 | F89: 1.054054 | G89: 2.125
A90: go.Top | B90: 70 | C90: 3x5 | D90: 15 | E90: 3x5 | F90: 1.0810811 | G90: 2.125
A91: go.Top | B91: 70 | C91: 64x0.6 | D91: 38.4 | E91: 64x0.6 | F91: 1.0789474 | G91: 1.888889
A92: go.Top | B92: 80 | C92: 6x0.6 | D92: 3.6 | E92: 6x0.6
A93: go.Top | B93: 80 | C93: 1x5 | D93: 5 | E93: 1x5 | F93: 1.0526316 | G93: 1.928571
A94: go.Top | B94: 80 | C94: 1x10 | D94: 10 | E94: 1x10 | F94: 1.0526316 | G94: 1.857143
A95: go.Top | B95: 80 | C95: 3x5 | D95: 15 | E95: 3x5 | F95: 1.0526316 | G95: 1.857143
A96: go.Top | B96: 80 | C96: 64x0.6 | D96: 38.4 | E96: 64x0.6 | F96: 1.0508475 | G96: 1.8
A97: go.Top | B97: 90 | C97: 6x0.6 | D97: 3.6 | E97: 6x0.6
A98: go.Top | B98: 90 | C98: 1x5 | D98: 5 | E98: 1x5 | F98: 1.0365854 | G98: 1.772727
...

Sheet Sheet18
A1: Model | B1: scanner_id | C1: manufacturer_id | D1: phantom_diameter | E1: shaped_filter | F1: kv | G1: spectral_filter | H1: coll_N | I1: coll_T | J1: coll_width | K1: ctdi100_center | L1: ctdi_w | M1: scanner_id | N1: manufacturer_id
A2: Confidence 64 | B2: =VLOOKUP(M2,Sheet9!$I$1:$J$17,2,FALSE) -> 8 | C2: =VLOOKUP(N2,Sheet9!$M$1:$N$2,2,FALSE) -> 1 | D2: 16 | E2: Standard | F2: 70 | H2: =_xlfn.NUMBERVALUE( LEFT(Sheet9!C2,SEARCH("x",Sheet9!C2)-1),".") -> 2 | I2: =_xlfn.NUMBERVALUE(RIGHT(Sheet9!C2,LEN(Sheet9!C2)-SEARCH("x",Sheet9!C2,1)),".") -> 1 | J2: =H2*I2 -> 2 | K2: 2.86 | L2: 3.06 | M2: Confidence 64 | N2: Siemens
A3: Confidence 64 | B3: =VLOOKUP(M3,Sheet9!$I$1:$J$17,2,FALSE) -> 8 | C3: =VLOOKUP(N3,Sheet9!$M$1:$N$2,2,FALSE) -> 1 | D3: 16 | E3: Standard | F3: 70 | H3: =_xlfn.NUMBERVALUE( LEFT(Sheet9!C3,SEARCH("x",Sheet9!C3)-1),".") -> 1 | I3: =_xlfn.NUMBERVALUE(RIGHT(Sheet9!C3,LEN(Sheet9!C3)-SEARCH("x",Sheet9!C3,1)),".") -> 5 | J3: =H3*I3 -> 5 | K3: 2.57 | L3: 2.74 | M3: Confidence 64 | N3: Siemens
A4: Confidence 64 | B4: =VLOOKUP(M4,Sheet9!$I$1:$J$17,2,FALSE) -> 8 | C4: =VLOOKUP(N4,Sheet9!$M$1:$N$2,2,FALSE) -> 1 | D4: 16 | E4: Standard | F4: 70 | H4: =_xlfn.NUMBERVALUE( LEFT(Sheet9!C4,SEARCH("x",Sheet9!C4)-1),".") -> 10 | I4: =_xlfn.NUMBERVALUE(RIGHT(Sheet9!C4,LEN(Sheet9!C4)-SEARCH("x",Sheet9!C4,1)),".") -> 0.6 | J4: =H4*I4 -> 6 | K4: 3.41 | L4: 3.63 | M4: Confidence 64 | N4: Siemens
A5: Confidence 64 | B5: =VLOOKUP(M5,Sheet9!$I$1:$J$17,2,FALSE) -> 8 | C5: =VLOOKUP(N5,Sheet9!$M$1:$N$2,2,FALSE) -> 1 | D5: 16 | E5: Standard | F5: 70 | H5: =_xlfn.NUMBERVALUE( LEFT(Sheet9!C5,SEARCH("x",Sheet9!C5)-1),".") -> 6 | I5: =_xlfn.NUMBERVALUE(RIGHT(Sheet9!C5,LEN(Sheet9!C5)-SEARCH("x",Sheet9!C5,1)),".") -> 1.2 | J5: =H5*I5 -> 7.2 | K5: 3.69 | L5: 3.94 | M5: Confidence 64 | N5: Siemens
A6: Confidence 64 | B6: =VLOOKUP(M6,Sheet9!$I$1:$J$17,2,FALSE) -> 8 | C6: =VLOOKUP(N6,Sheet9!$M$1:$N$2,2,FALSE) -> 1 | D6: 16 | E6: Standard | F6: 70 | H6: =_xlfn.NUMBERVALUE( LEFT(Sheet9!C6,SEARCH("x",Sheet9!C6)-1),".") -> 1 | I6: =_xlfn.NUMBERVALUE(RIGHT(Sheet9!C6,LEN(Sheet9!C6)-SEARCH("x",Sheet9!C6,1)),".") -> 10 | J6: =H6*I6 -> 10 | K6: 2.57 | L6: 2.74 | M6: Confidence 64 | N6: Siemens
A7: Confidence 64 | B7: =VLOOKUP(M7,Sheet9!$I$1:$J$17,2,FALSE) -> 8 | C7: =VLOOKUP(N7,Sheet9!$M$1:$N$2,2,FALSE) -> 1 | D7: 16 | E7: Standard | F7: 70 | H7: =_xlfn.NUMBERVALUE( LEFT(Sheet9!C7,SEARCH("x",Sheet9!C7)-1),".") -> 20 | I7: =_xlfn.NUMBERVALUE(RIGHT(Sheet9!C7,LEN(Sheet9!C7)-SEARCH("x",Sheet9!C7,1)),".") -> 0.6 | J7: =H7*I7 -> 12 | K7: 3.48 | L7: 3.7 | M7: Confidence 64 | N7: Siemens
A8: Confidence 64 | B8: =VLOOKUP(M8,Sheet9!$I$1:$J$17,2,FALSE) -> 8 | C8: =VLOOKUP(N8,Sheet9!$M$1:$N$2,2,FALSE) -> 1 | D8: 16 | E8: Standard | F8: 70 | H8: =_xlfn.NUMBERVALUE( LEFT(Sheet9!C8,SEARCH("x",Sheet9!C8)-1),".") -> 12 | I8: =_xlfn.NUMBERVALUE(RIGHT(Sheet9!C8,LEN(Sheet9!C8)-SEARCH("x",Sheet9!C8,1)),".") -> 1.2 | J8: =H8*I8 -> 14.4 | K8: 3.29 | L8: 3.52 | M8: Confidence 64 | N8: Siemens
A9: Confidence 64 | B9: =VLOOKUP(M9,Sheet9!$I$1:$J$17,2,FALSE) -> 8 | C9: =VLOOKUP(N9,Sheet9!$M$1:$N$2,2,FALSE) -> 1 | D9: 16 | E9: Standard | F9: 70 | H9: =_xlfn.NUMBERVALUE( LEFT(Sheet9!C9,SEARCH("x",Sheet9!C9)-1),".") -> 32 | I9: =_xlfn.NUMBERVALUE(RIGHT(Sheet9!C9,LEN(Sheet9!C9)-SEARCH("x",Sheet9!C9,1)),".") -> 0.6 | J9: =H9*I9 -> 19.2 | K9: 3.24 | L9: 3.44 | M9: Confidence 64 | N9: Siemens
A10: Confidence 64 | B10: =VLOOKUP(M10,Sheet9!$I$1:$J$17,2,FALSE) -> 8 | C10: =VLOOKUP(N10,Sheet9!$M$1:$N$2,2,FALSE) -> 1 | D10: 16 | E10: Standard | F10: 70 | H10: =_xlfn.NUMBERVALUE( LEFT(Sheet9!C10,SEARCH("x",Sheet9!C10)-1),".") -> 16 | I10: =_xlfn.NUMBERVALUE(RIGHT(Sheet9!C10,LEN(Sheet9!C10)-SEARCH("x",Sheet9!C10,1)),".") -> 1.2 | J10: =H10*I10 -> 19.2 | K10: 3.15 | L10: 3.37 | M10: Confidence 64 | N10: Siemens
A11: Confidence 64 | B11: =VLOOKUP(M11,Sheet9!$I$1:$J$17,2,FALSE) -> 8 | C11: =VLOOKUP(N11,Sheet9!$M$1:$N$2,2,FALSE) -> 1 | D11: 16 | E11: Standard | F11: 80 | H11: =_xlfn.NUMBERVALUE( LEFT(Sheet9!C11,SEARCH("x",Sheet9!C11)-1),".") -> 2 | I11: =_xlfn.NUMBERVALUE(RIGHT(Sheet9!C11,LEN(Sheet9!C11)-SEARCH("x",Sheet9!C11,1)),".") -> 1 | J11: =H11*I11 -> 2 | K11: 4.57 | L11: 4.77 | M11: Confidence 64 | N11: Siemens
A12: Confidence 64 | B12: =VLOOKUP(M12,Sheet9!$I$1:$J$17,2,FALSE) -> 8 | C12: =VLOOKUP(N12,Sheet9!$M$1:$N$2,2,FALSE) -> 1 | D12: 16 | E12: Standard | F12: 80 | H12: =_xlfn.NUMBERVALUE( LEFT(Sheet9!C12,SEARCH("x",Sheet9!C12)-1),".") -> 1 | I12: =_xlfn.NUMBERVALUE(RIGHT(Sheet9!C12,LEN(Sheet9!C12)-SEARCH("x",Sheet9!C12,1)),".") -> 5 | J12: =H12*I12 -> 5 | K12: 4.1 | L12: 4.28 | M12: Confidence 64 | N12: Siemens
A13: Confidence 64 | B13: =VLOOKUP(M13,Sheet9!$I$1:$J$17,2,FALSE) -> 8 | C13: =VLOOKUP(N13,Sheet9!$M$1:$N$2,2,FALSE) -> 1 | D13: 16 | E13: Standard | F13: 80 | H13: =_xlfn.NUMBERVALUE( LEFT(Sheet9!C13,SEARCH("x",Sheet9!C13)-1),".") -> 10 | I13: =_xlfn.NUMBERVALUE(RIGHT(Sheet9!C13,LEN(Sheet9!C13)-SEARCH("x",Sheet9!C13,1)),".") -> 0.6 | J13: =H13*I13 -> 6 | K13: 5.44 | L13: 5.67 | M13: Confidence 64 | N13: Siemens
... A46: Confidence 64 | B46: =VLOOKUP(M46,Sheet9!$I$1:$J$17,2,FALSE) -> 8 | C46: =VLOOKUP(N46,Sheet9!$M$1:$N$2,2,FALSE) -> 1 | D46: 16 | E46: Standard | F46: 140 | H46: =_xlfn.NUMBERVALUE( LEFT(Sheet9!C46,SEARCH("x",Sheet9!C46)-1),".") -> 16 | I46: =_xlfn.NUMBERVALUE(RIGHT(Sheet9!C46,LEN(Sheet9!C46)-SEARCH("x",Sheet9!C46,1)),".") -> 1.2 | J46: =H46*I46 -> 19.2 | K46: 23.37 | L46: 23.54 | M46: Confidence 64 | N46: Siemens
A47: Confidence 64 | B47: =VLOOKUP(M47,Sheet9!$I$1:$J$17,2,FALSE) -> 8 | C47: =VLOOKUP(N47,Sheet9!$M$1:$N$2,2,FALSE) -> 1 | D47: 16 | E47: Narrow | F47: 70 | H47: 2 | I47: 1 | J47: 2 | K47: 2.54 | L47: 2.55 | M47: Confidence 64 | N47: Siemens
A48: Confidence 64 | B48: =VLOOKUP(M48,Sheet9!$I$1:$J$17,2,FALSE) -> 8 | C48: =VLOOKUP(N48,Sheet9!$M$1:$N$2,2,FALSE) -> 1 | D48: 16 | E48: Narrow | F48: 70 | H48: 1 | I48: 5 | J48: 5 | K48: 2.28 | L48: 2.28 | M48: Confidence 64 | N48: Siemens
A49: Confidence 64 | B49: =VLOOKUP(M49,Sheet9!$I$1:$J$17,2,FALSE) -> 8 | C49: =VLOOKUP(N49,Sheet9!$M$1:$N$2,2,FALSE) -> 1 | D49: 16 | E49: Narrow | F49: 70 | H49: 10 | I49: 0.6 | J49: 6 | K49: 3.02 | L49: 3.01 | M49: Confidence 64 | N49: Siemens
A50: Confidence 64 | B50: =VLOOKUP(M50,Sheet9!$I$1:$J$17,2,FALSE) -> 8 | C50: =VLOOKUP(N50,Sheet9!$M$1:$N$2,2,FALSE) -> 1 | D50: 16 | E50: Narrow | F50: 70 | H50: 6 | I50: 1.2 | J50: 7.2 | K50: 3.28 | L50: 3.28 | M50: Confidence 64 | N50: Siemens
A51: Confidence 64 | B51: =VLOOKUP(M51,Sheet9!$I$1:$J$17,2,FALSE) -> 8 | C51: =VLOOKUP(N51,Sheet9!$M$1:$N$2,2,FALSE) -> 1 | D51: 16 | E51: Narrow | F51: 70 | H51: 1 | I51: 10 | J51: 10 | K51: 2.28 | L51: 2.28 | M51: Confidence 64 | N51: Siemens
A52: Confidence 64 | B52: =VLOOKUP(M52,Sheet9!$I$1:$J$17,2,FALSE) -> 8 | C52: =VLOOKUP(N52,Sheet9!$M$1:$N$2,2,FALSE) -> 1 | D52: 16 | E52: Narrow | F52: 70 | H52: 20 | I52: 0.6 | J52: 12 | K52: 3.08 | L52: 3.07 | M52: Confidence 64 | N52: Siemens
A53: Confidence 64 | B53: =VLOOKUP(M53,Sheet9!$I$1:$J$17,2,FALSE) -> 8 | C53: =VLOOKUP(N53,Sheet9!$M$1:$N$2,2,FALSE) -> 1 | D53: 16 | E53: Narrow | F53: 70 | H53: 12 | I53: 1.2 | J53: 14.4 | K53: 2.93 | L53: 2.93 | M53: Confidence 64 | N53: Siemens
A54: Confidence 64 | B54: =VLOOKUP(M54,Sheet9!$I$1:$J$17,2,FALSE) -> 8 | C54: =VLOOKUP(N54,Sheet9!$M$1:$N$2,2,FALSE) -> 1 | D54: 16 | E54: Narrow | F54: 70 | H54: 32 | I54: 0.6 | J54: 19.2 | K54: 2.87 | L54: 2.86 | M54: Confidence 64 | N54: Siemens
A55: Confidence 64 | B55: =VLOOKUP(M55,Sheet9!$I$1:$J$17,2,FALSE) -> 8 | C55: =VLOOKUP(N55,Sheet9!$M$1:$N$2,2,FALSE) -> 1 | D55: 16 | E55: Narrow | F55: 70 | H55: 16 | I55: 1.2 | J55: 19.2 | K55: 2.8 | L55: 2.8 | M55: Confidence 64 | N55: Siemens
A56: Confidence 64 | B56: =VLOOKUP(M56,Sheet9!$I$1:$J$17,2,FALSE) -> 8 | C56: =VLOOKUP(N56,Sheet9!$M$1:$N$2,2,FALSE) -> 1 | D56: 16 | E56: Narrow | F56: 80 | H56: 2 | I56: 1 | J56: 2 | K56: 4.11 | L56: 4.05 | M56: Confidence 64 | N56: Siemens
A57: Confidence 64 | B57: =VLOOKUP(M57,Sheet9!$I$1:$J$17,2,FALSE) -> 8 | C57: =VLOOKUP(N57,Sheet9!$M$1:$N$2,2,FALSE) -> 1 | D57: 16 | E57: Narrow | F57: 80 | H57: 1 | I57: 5 | J57: 5 | K57: 3.69 | L57: 3.64 | M57: Confidence 64 | N57: Siemens
A58: Confidence 64 | B58: =VLOOKUP(M58,Sheet9!$I$1:$J$17,2,FALSE) -> 8 | C58: =VLOOKUP(N58,Sheet9!$M$1:$N$2,2,FALSE) -> 1 | D58: 16 | E58: Narrow | F58: 80 | H58: 10 | I58: 0.6 | J58: 6 | K58: 4.91 | L58: 4.8 | M58: Confidence 64 | N58: Siemens
... A389: Pro.Pulse A tube | B389: =VLOOKUP(M389,Sheet9!$I$1:$J$17,2,FALSE) -> 14 | C389: =VLOOKUP(N389,Sheet9!$M$1:$N$2,2,FALSE) -> 1 | D389: 16 | E389: Standard | F389: 140 | H389: 64 | I389: 0.6 | J389: 38.4 | K389: 29 | L389: 29.75 | M389: Pro.Pulse A tube | N389: Siemens
A390: Pro.Pulse A tube | B390: =VLOOKUP(M390,Sheet9!$I$1:$J$17,2,FALSE) -> 14 | C390: =VLOOKUP(N390,Sheet9!$M$1:$N$2,2,FALSE) -> 1 | D390: 16 | E390: Standard | F390: 100 | G390: Sn | H390: 1 | I390: 5 | J390: 5 | M390: Pro.Pulse A tube | N390: Siemens
A391: Pro.Pulse A tube | B391: =VLOOKUP(M391,Sheet9!$I$1:$J$17,2,FALSE) -> 14 | C391: =VLOOKUP(N391,Sheet9!$M$1:$N$2,2,FALSE) -> 1 | D391: 16 | E391: Standard | F391: 100 | G391: Sn | H391: 1 | I391: 10 | J391: 10 | M391: Pro.Pulse A tube | N391: Siemens
A392: Pro.Pulse A tube | B392: =VLOOKUP(M392,Sheet9!$I$1:$J$17,2,FALSE) -> 14 | C392: =VLOOKUP(N392,Sheet9!$M$1:$N$2,2,FALSE) -> 1 | D392: 16 | E392: Standard | F392: 100 | G392: Sn | H392: 3 | I392: 3 | J392: 9 | K392: 2.11 | L392: 2.13 | M392: Pro.Pulse A tube | N392: Siemens
A393: Pro.Pulse A tube | B393: =VLOOKUP(M393,Sheet9!$I$1:$J$17,2,FALSE) -> 14 | C393: =VLOOKUP(N393,Sheet9!$M$1:$N$2,2,FALSE) -> 1 | D393: 16 | E393: Standard | F393: 100 | G393: Sn | H393: 3 | I393: 5 | J393: 15 | K393: 1.92 | L393: 1.93 | M393: Pro.Pulse A tube | N393: Siemens
A394: Pro.Pulse A tube | B394: =VLOOKUP(M394,Sheet9!$I$1:$J$17,2,FALSE) -> 14 | C394: =VLOOKUP(N394,Sheet9!$M$1:$N$2,2,FALSE) -> 1 | D394: 16 | E394: Standard | F394: 100 | G394: Sn | H394: 32 | I394: 0.6 | J394: 19.2 | M394: Pro.Pulse A tube | N394: Siemens
A395: Pro.Pulse A tube | B395: =VLOOKUP(M395,Sheet9!$I$1:$J$17,2,FALSE) -> 14 | C395: =VLOOKUP(N395,Sheet9!$M$1:$N$2,2,FALSE) -> 1 | D395: 16 | E395: Standard | F395: 100 | G395: Sn | H395: 64 | I395: 0.6 | J395: 38.4 | K395: 2 | L395: 2.02 | M395: Pro.Pulse A tube | N395: Siemens
A396: Pro.Pulse A tube | B396: =VLOOKUP(M396,Sheet9!$I$1:$J$17,2,FALSE) -> 14 | C396: =VLOOKUP(N396,Sheet9!$M$1:$N$2,2,FALSE) -> 1 | D396: 16 | E396: Standard | F396: 110 | G396: Sn | H396: 1 | I396: 5 | J396: 5 | M396: Pro.Pulse A tube | N396: Siemens
A397: Pro.Pulse A tube | B397: =VLOOKUP(M397,Sheet9!$I$1:$J$17,2,FALSE) -> 14 | C397: =VLOOKUP(N397,Sheet9!$M$1:$N$2,2,FALSE) -> 1 | D397: 16 | E397: Standard | F397: 110 | G397: Sn | H397: 1 | I397: 10 | J397: 10 | M397: Pro.Pulse A tube | N397: Siemens
A398: Pro.Pulse A tube | B398: =VLOOKUP(M398,Sheet9!$I$1:$J$17,2,FALSE) -> 14 | C398: =VLOOKUP(N398,Sheet9!$M$1:$N$2,2,FALSE) -> 1 | D398: 16 | E398: Standard | F398: 110 | G398: Sn | H398: 3 | I398: 3 | J398: 9 | K398: 3.26 | L398: 3.3 | M398: Pro.Pulse A tube | N398: Siemens
A399: Pro.Pulse A tube | B399: =VLOOKUP(M399,Sheet9!$I$1:$J$17,2,FALSE) -> 14 | C399: =VLOOKUP(N399,Sheet9!$M$1:$N$2,2,FALSE) -> 1 | D399: 16 | E399: Standard | F399: 110 | G399: Sn | H399: 3 | I399: 5 | J399: 15 | K399: 2.97 | L399: 3 | M399: Pro.Pulse A tube | N399: Siemens
A400: Pro.Pulse A tube | B400: =VLOOKUP(M400,Sheet9!$I$1:$J$17,2,FALSE) -> 14 | C400: =VLOOKUP(N400,Sheet9!$M$1:$N$2,2,FALSE) -> 1 | D400: 16 | E400: Standard | F400: 110 | G400: Sn | H400: 32 | I400: 0.6 | J400: 19.2 | M400: Pro.Pulse A tube | N400: Siemens
A401: Pro.Pulse A tube | B401: =VLOOKUP(M401,Sheet9!$I$1:$J$17,2,FALSE) -> 14 | C401: =VLOOKUP(N401,Sheet9!$M$1:$N$2,2,FALSE) -> 1 | D401: 16 | E401: Standard | F401: 110 | G401: Sn | H401: 64 | I401: 0.6 | J401: 38.4 | K401: 3.1 | L401: 3.14 | M401: Pro.Pulse A tube | N401: Siemens
A402: Pro.Pulse A tube | B402: =VLOOKUP(M402,Sheet9!$I$1:$J$17,2,FALSE) -> 14 | C402: =VLOOKUP(N402,Sheet9!$M$1:$N$2,2,FALSE) -> 1 | D402: 16 | E402: Standard | F402: 120 | G402: Sn | H402: 1 | I402: 5 | J402: 5 | M402: Pro.Pulse A tube | N402: Siemens
...

Sheet Pro.Pulse
A1: 16 cm phantom, Standard shaped filter (Routine head)
C2: Tube A | I2: Tube B
B3: Collimation | C3: 1x5 | D3: 1x10 | E3: 3x3 | F3: 3x5 | G3: 32x0.6 | H3: 64x0.6 | I3: 32x0.6 | J3: 64x0.6
B4: Acquisition | C4: 1x5 | D4: 1x10 | E4: 3x3 | F4: 3x5 | G4: 32x0.6 | H4: 64x0.6 | I4: 32x0.6 | J4: 64x0.6
A5: kV
A6: 70 | B6: Center | C6: 4.07 | D6: 4.01 | E6: 4.45 | F6: 4.04 | G6: 4.73 | H6: 4.18 | J6: 4.4
B7: CTDIw | C7: 4.39 | D7: 4.32 | E7: 4.8 | F7: 4.35 | G7: 5.1 | H7: 4.52 | J7: 4.74
B8: k | C8: =IF(OR(C6="",C7=""),"",C7/C6) -> 1.0786241 | D8: =IF(OR(D6="",D7=""),"",D7/D6) -> 1.0773067 | E8: =IF(OR(E6="",E7=""),"",E7/E6) -> 1.0786517 | F8: =IF(OR(F6="",F7=""),"",F7/F6) -> 1.0767327 | G8: =IF(OR(G6="",G7=""),"",G7/G6) -> 1.0782241 | H8: =IF(OR(H6="",H7=""),"",H7/H6) -> 1.0813397 | I8: =IF(OR(I6="",I7=""),"",I7/I6) | J8: =IF(OR(J6="",J7=""),"",J7/J6) -> 1.0772727
A9: 80 | B9: Center | C9: 6.44 | D9: 6.34 | E9: 7.04 | F9: 6.39 | G9: 7.49 | H9: 6.61 | J9: 6.92
B10: CTDIw | C10: 6.81 | D10: 6.69 | E10: 7.43 | F10: 6.74 | G10: 7.9 | H10: 7 | J10: 7.32
B11: k | C11: =IF(OR(C9="",C10=""),"",C10/C9) -> 1.0574534 | D11: =IF(OR(D9="",D10=""),"",D10/D9) -> 1.055205 | E11: =IF(OR(E9="",E10=""),"",E10/E9) -> 1.0553977 | F11: =IF(OR(F9="",F10=""),"",F10/F9) -> 1.0547731 | G11: =IF(OR(G9="",G10=""),"",G10/G9) -> 1.0547397 | H11: =IF(OR(H9="",H10=""),"",H10/H9) -> 1.0590015 | I11: =IF(OR(I9="",I10=""),"",I10/I9) | J11: =IF(OR(J9="",J10=""),"",J10/J9) -> 1.0578035
A12: 90 | B12: Center | C12: 9.29 | D12: 9.13 | E12: 10.14 | F12: 9.2 | G12: 10.77 | H12: 9.51 | J12: 9.92
B13: CTDIw | C13: 9.69 | D13: 9.53 | E13: 10.59 | F13: 9.6 | G13: 11.25 | H13: 9.96 | J13: 10.38
B14: k | C14: =IF(OR(C12="",C13=""),"",C13/C12) -> 1.0430571 | D14: =IF(OR(D12="",D13=""),"",D13/D12) -> 1.0438116 | E14: =IF(OR(E12="",E13=""),"",E13/E12) -> 1.0443787 | F14: =IF(OR(F12="",F13=""),"",F13/F12) -> 1.0434783 | G14: =IF(OR(G12="",G13=""),"",G13/G12) -> 1.0445682 | H14: =IF(OR(H12="",H13=""),"",H13/H12) -> 1.0473186 | I14: =IF(OR(I12="",I13=""),"",I13/I12) | J14: =IF(OR(J12="",J13=""),"",J13/J12) -> 1.046371
A15: 100 | B15: Center | C15: 12.52 | D15: 12.31 | E15: 13.68 | F15: 12.42 | G15: 14.53 | H15: 12.81 | J15: 13.32
B16: CTDIw | C16: 12.96 | D16: 12.75 | E16: 14.17 | F16: 12.85 | G16: 15.04 | H16: 13.3 | J16: 13.84
B17: k | C17: =IF(OR(C15="",C16=""),"",C16/C15) -> 1.0351438 | D17: =IF(OR(D15="",D16=""),"",D16/D15) -> 1.0357433 | E17: =IF(OR(E15="",E16=""),"",E16/E15) -> 1.0358187 | F17: =IF(OR(F15="",F16=""),"",F16/F15) -> 1.0346216 | G17: =IF(OR(G15="",G16=""),"",G16/G15) -> 1.0350998 | H17: =IF(OR(H15="",H16=""),"",H16/H15) -> 1.0382514 | I17: =IF(OR(I15="",I16=""),"",I16/I15) | J17: =IF(OR(J15="",J16=""),"",J16/J15) -> 1.039039
A18: 110 | B18: Center | C18: 15.99 | D18: 15.79 | E18: 17.54 | F18: 15.9 | G18: 18.64 | H18: 16.42 | J18: 17.02
B19: CTDIw | C19: 16.57 | D19: 16.3 | E19: 18.11 | F19: 16.4 | G19: 19.21 | H19: 16.98 | J19: 17.62
B20: k | C20: =IF(OR(C18="",C19=""),"",C19/C18) -> 1.0362727 | D20: =IF(OR(D18="",D19=""),"",D19/D18) -> 1.0322989 | E20: =IF(OR(E18="",E19=""),"",E19/E18) -> 1.0324971 | F20: =IF(OR(F18="",F19=""),"",F19/F18) -> 1.0314465 | G20: =IF(OR(G18="",G19=""),"",G19/G18) -> 1.0305794 | H20: =IF(OR(H18="",H19=""),"",H19/H18) -> 1.0341048 | I20: =IF(OR(I18="",I19=""),"",I19/I18) | J20: =IF(OR(J18="",J19=""),"",J19/J18) -> 1.0352526
A21: 120 | B21: Center | C21: 19.92 | D21: 19.6 | E21: 21.77 | F21: 19.71 | G21: 23.08 | H21: 20.34 | J21: 21.08
B22: CTDIw | C22: 20.5 | D22: 20.13 | E22: 22.37 | F22: 20.26 | G22: 23.73 | H22: 20.96 | J22: 21.72
B23: k | C23: =IF(OR(C21="",C22=""),"",C22/C21) -> 1.0291165 | D23: =IF(OR(D21="",D22=""),"",D22/D21) -> 1.0270408 | E23: =IF(OR(E21="",E22=""),"",E22/E21) -> 1.0275609 | F23: =IF(OR(F21="",F22=""),"",F22/F21) -> 1.0279046 | G23: =IF(OR(G21="",G22=""),"",G22/G21) -> 1.0281629 | H23: =IF(OR(H21="",H22=""),"",H22/H21) -> 1.0304818 | I23: =IF(OR(I21="",I22=""),"",I22/I21) | J23: =IF(OR(J21="",J22=""),"",J22/J21) -> 1.0303605
A24: 130 | B24: Center | C24: 24.1 | D24: 23.69 | E24: 26.32 | F24: 23.81 | G24: 27.89 | H24: 24.52 | J24: 25.36
B25: CTDIw | C25: 24.72 | D25: 24.26 | E25: 26.95 | F25: 24.41 | G25: 28.57 | H25: 25.22 | J25: 26.1
B26: k | C26: =IF(OR(C24="",C25=""),"",C25/C24) -> 1.0257261 | D26: =IF(OR(D24="",D25=""),"",D25/D24) -> 1.0240608 | E26: =IF(OR(E24="",E25=""),"",E25/E24) -> 1.0239362 | F26: =IF(OR(F24="",F25=""),"",F25/F24) -> 1.0251995 | G26: =IF(OR(G24="",G25=""),"",G25/G24) -> 1.0243815 | H26: =IF(OR(H24="",H25=""),"",H25/H24) -> 1.0285481 | I26: =IF(OR(I24="",I25=""),"",I25/I24) | J26: =IF(OR(J24="",J25=""),"",J25/J24) -> 1.0291798
A27: 140 | B27: Center | C27: 28.32 | D27: 27.94 | E27: 31.04 | F27: 28.13 | G27: 23.89 | H27: 29 | J27: 30
B28: CTDIw | C28: 29.08 | D28: 28.6 | E28: 31.78 | F28: 28.77 | G28: 33.69 | H28: 29.75 | J28: 30.77
B29: k | C29: =IF(OR(C27="",C28=""),"",C28/C27) -> 1.0268362 | D29: =IF(OR(D27="",D28=""),"",D28/D27) -> 1.023622 | E29: =IF(OR(E27="",E28=""),"",E28/E27) -> 1.0238402 | F29: =IF(OR(F27="",F28=""),"",F28/F27) -> 1.0227515 | G29: =IF(OR(G27="",G28=""),"",G28/G27) -> 1.4102135 | H29: =IF(OR(H27="",H28=""),"",H28/H27) -> 1.0258621 | I29: =IF(OR(I27="",I28=""),"",I28/I27) | J29: =IF(OR(J27="",J28=""),"",J28/J27) -> 1.0256667
A30: 100Sn | B30: Center | E30: 2.11 | F30: 1.92 | H30: 2 | I30: 2.41 | J30: 2.08
B31: CTDIw | E31: 2.13 | F31: 1.93 | H31: 2.02 | I31: 2.42 | J31: 2.11
B32: k | C32: =IF(OR(C30="",C31=""),"",C31/C30) | D32: =IF(OR(D30="",D31=""),"",D31/D30) | E32: =IF(OR(E30="",E31=""),"",E31/E30) -> 1.0094787 | F32: =IF(OR(F30="",F31=""),"",F31/F30) -> 1.0052083 | G32: =IF(OR(G30="",G31=""),"",G31/G30) | H32: =IF(OR(H30="",H31=""),"",H31/H30) -> 1.01 | I32: =IF(OR(I30="",I31=""),"",I31/I30) -> 1.0041494 | J32: =IF(OR(J30="",J31=""),"",J31/J30) -> 1.0144231
A33: 110Sn | B33: Center | E33: 3.26 | F33: 2.97 | H33: 3.1 | I33: 3.71 | J33: 3.22
B34: CTDIw | E34: 3.3 | F34: 3 | H34: 3.14 | I34: 3.7 | J34: 3.26
B35: k | C35: =IF(OR(C33="",C34=""),"",C34/C33) | D35: =IF(OR(D33="",D34=""),"",D34/D33) | E35: =IF(OR(E33="",E34=""),"",E34/E33) -> 1.0122699 | F35: =IF(OR(F33="",F34=""),"",F34/F33) -> 1.010101 | G35: =IF(OR(G33="",G34=""),"",G34/G33) | H35: =IF(OR(H33="",H34=""),"",H34/H33) -> 1.0129032 | I35: =IF(OR(I33="",I34=""),"",I34/I33) -> 0.99730458 | J35: =IF(OR(J33="",J34=""),"",J34/J33) -> 1.0124224
A36: 120Sn | B36: Center | E36: 4.72 | F36: 4.29 | H36: 4.47 | I36: 5.35 | J36: 4.63
B37: CTDIw | E37: 4.77 | F37: 4.33 | H37: 4.53 | I37: 5.41 | J37: 4.69
B38: k | C38: =IF(OR(C36="",C37=""),"",C37/C36) | D38: =IF(OR(D36="",D37=""),"",D37/D36) | E38: =IF(OR(E36="",E37=""),"",E37/E36) -> 1.0105932 | F38: =IF(OR(F36="",F37=""),"",F37/F36) -> 1.009324 | G38: =IF(OR(G36="",G37=""),"",G37/G36) | H38: =IF(OR(H36="",H37=""),"",H37/H36) -> 1.0134228 | I38: =IF(OR(I36="",I37=""),"",I37/I36) -> 1.011215 | J38: =IF(OR(J36="",J37=""),"",J37/J36) -> 1.012959
A39: 130Sn | B39: Center | E39: 6.47 | F39: 5.87 | H39: 6.11 | I39: 7.33 | J39: 6.33
B40: CTDIw | E40: 6.55 | F40: 5.95 | H40: 6.21 | I40: 7.41 | J40: 6.43
...

Sheet Neurologica BodyTom
A1: 16 cm phantom (Adult head)
B2: Collimation | C2: 16x0.6 | E2: 7.9 | F2: 9.46
B3: Total | C3: =16*0.6 -> 9.6 | E3: 16.23 | F3: 18.1
B4: Acquisition | C4: 16x0.6 | E4: 24.62 | F4: 27.07
B5: Shaped filter | E5: 35 | F5: 37.74
A6: kV | E6: 1.49 | F6: 3.15
A7: 80 | B7: Center | C7: 7.9 | E7: 3.08 | F7: 5.85
B8: CTDIw | C8: 9.46 | E8: 5.53 | F8: 9.23
B9: k | C9: =IF(OR(C7="",C8=""),"",C8/C7) -> 1.1974684 | E9: 8.26 | F9: 13.13
A10: 100 | B10: Center | C10: 16.23
B11: CTDIw | C11: 18.1
B12: k | C12: =IF(OR(C10="",C11=""),"",C11/C10) -> 1.1152187
A13: 120 | B13: Center | C13: 24.62
B14: CTDIw | C14: 27.07
B15: k | C15: =IF(OR(C13="",C14=""),"",C14/C13) -> 1.0995126
A16: 140 | B16: Center | C16: 35
B17: CTDIw | C17: 37.74
B18: k | C18: =IF(OR(C16="",C17=""),"",C17/C16) -> 1.0782857
A20: 32 cm phantom (Adult body)
B21: Collimation | C21: 64x0.6
B22: Total | C22: 38.4
B23: Acquisition | C23: 64x0.6
B24: Shaped filter
A25: kV
A26: 80 | B26: Center | C26: 1.49
B27: CTDIw | C27: 3.15
B28: k | C28: =IF(OR(C26="",C27=""),"",C27/C26) -> 2.114094
A29: 100 | B29: Center | C29: 3.08
B30: CTDIw | C30: 5.85
B31: k | C31: =IF(OR(C29="",C30=""),"",C30/C29) -> 1.8993506
A32: 120 | B32: Center | C32: 5.53
B33: CTDIw | C33: 9.23
B34: k | C34: =IF(OR(C32="",C33=""),"",C33/C32) -> 1.6690778
A35: 140 | B35: Center | C35: 8.26
B36: CTDIw | C36: 13.13
B37: k | C37: =IF(OR(C35="",C36=""),"",C36/C35) -> 1.5895884

Sheet Symbia Pro.specta Q3
A1: 16 cm phantom (Adult head) | I1: 5.33 | J1: 5.92
B2: Collimation | C2: 1x5 | D2: 1x10 | E2: 3x3 | F2: 16x0.7 | G2: 16x0.7 (Sn) | I2: 5.36 | J2: 5.93
B3: Total | C3: 5 | D3: 10 | E3: 9 | F3: 11.2 | G3: 11.2 | I3: 5.96 | J3: 6.59
B4: Acquisition | C4: 1x5 | D4: 1x10 | E4: 3x3 | F4: 16x0.7 | G4: 16x0.7 (Sn) | I4: 6.38 | J4: 7.08
B5: Shaped filter
A6: kV | I6: 13.33 | J6: 14.3
A7: 80 | B7: Center | C7: 5.33 | D7: 5.36 | E7: 5.96 | F7: 6.38 | I7: 13.39 | J7: 14.32
B8: CTDIw | C8: 5.92 | D8: 5.93 | E8: 6.59 | F8: 7.08 | I8: 14.87 | J8: 15.92
B9: k | C9: =IF(OR(C7="",C8=""),"",C8/C7) -> 1.1106942 | D9: =IF(OR(D7="",D8=""),"",D8/D7) -> 1.1063433 | E9: =IF(OR(E7="",E8=""),"",E8/E7) -> 1.1057047 | F9: =IF(OR(F7="",F8=""),"",F8/F7) -> 1.1097179 | G9: =IF(OR(G7="",G8=""),"",G8/G7) | I9: 15.98 | J9: 17.1
A10: 110 | B10: Center | C10: 13.33 | D10: 13.39 | E10: 14.87 | F10: 15.98 | G10: 2.99 | I10: 2.99 | J10: 3.08
B11: CTDIw | C11: 14.3 | D11: 14.32 | E11: 15.92 | F11: 17.1 | G11: 3.08 | I11: 20.27 | J11: 21.52
B12: k | C12: =IF(OR(C10="",C11=""),"",C11/C10) -> 1.0727682 | D12: =IF(OR(D10="",D11=""),"",D11/D10) -> 1.0694548 | E12: =IF(OR(E10="",E11=""),"",E11/E10) -> 1.070612 | F12: =IF(OR(F10="",F11=""),"",F11/F10) -> 1.0700876 | G12: =IF(OR(G10="",G11=""),"",G11/G10) -> 1.0301003 | I12: 20.27 | J12: 21.52
A13: 130 | B13: Center | C13: 20.27 | D13: 20.27 | E13: 22.52 | F13: 24.24 | G13: 5.86 | I13: 22.52 | J13: 23.91
B14: CTDIw | C14: 21.52 | D14: 21.52 | E14: 23.91 | F14: 25.7 | G14: 6.05 | I14: 24.24 | J14: 25.7
B15: k | C15: =IF(OR(C13="",C14=""),"",C14/C13) -> 1.0616675 | D15: =IF(OR(D13="",D14=""),"",D14/D13) -> 1.0616675 | E15: =IF(OR(E13="",E14=""),"",E14/E13) -> 1.0617229 | F15: =IF(OR(F13="",F14=""),"",F14/F13) -> 1.060231 | G15: =IF(OR(G13="",G14=""),"",G14/G13) -> 1.0324232 | I15: 5.86 | J15: 6.05
I16: 1.36 | J16: 2.64
A17: 32 cm phantom (Adult body) | I17: 1.36 | J17: 2.64
B18: Collimation | C18: 1x5 | D18: 1x10 | E18: 3x3 | F18: 16x0.7 | G18: 16x0.7 (Sn) | I18: 1.51 | J18: 2.94
B19: Total | C19: 5 | D19: 10 | E19: 9 | F19: 11.2 | G19: 11.2 | I19: 1.62 | J19: 3.15
B20: Acquisition | C20: 1x5 | D20: 1x10 | E20: 3x3 | F20: 16x0.7 | G20: 16x0.7 (Sn)
B21: Shaped filter | I21: 3.98 | J21: 6.82
A22: kV | I22: 3.97 | J22: 6.83
A23: 80 | B23: Center | C23: 1.36 | D23: 1.36 | E23: 1.51 | F23: 1.62 | I23: 4.41 | J23: 7.59
B24: CTDIw | C24: 2.64 | D24: 2.64 | E24: 2.94 | F24: 3.15 | I24: 4.75 | J24: 8.13
B25: k | C25: =IF(OR(C23="",C24=""),"",C24/C23) -> 1.9411765 | D25: =IF(OR(D23="",D24=""),"",D24/D23) -> 1.9411765 | E25: =IF(OR(E23="",E24=""),"",E24/E23) -> 1.9470199 | F25: =IF(OR(F23="",F24=""),"",F24/F23) -> 1.9444444 | G25: =IF(OR(G23="",G24=""),"",G24/G23) | I25: 1.09 | J25: 1.65
A26: 110 | B26: Center | C26: 3.98 | D26: 3.97 | E26: 4.41 | F26: 4.75 | G26: 1.09 | I26: 6.4 | J26: 10.57
B27: CTDIw | C27: 6.82 | D27: 6.83 | E27: 7.59 | F27: 8.13 | G27: 1.65 | I27: 6.39 | J27: 10.57
B28: k | C28: =IF(OR(C26="",C27=""),"",C27/C26) -> 1.7135678 | D28: =IF(OR(D26="",D27=""),"",D27/D26) -> 1.720403 | E28: =IF(OR(E26="",E27=""),"",E27/E26) -> 1.7210884 | F28: =IF(OR(F26="",F27=""),"",F27/F26) -> 1.7115789 | G28: =IF(OR(G26="",G27=""),"",G27/G26) -> 1.5137615 | I28: 7.1 | J28: 11.74
A29: 130 | B29: Center | C29: 6.4 | D29: 6.39 | E29: 7.1 | F29: 7.63 | G29: 2.23 | I29: 7.63 | J29: 12.57
B30: CTDIw | C30: 10.57 | D30: 10.57 | E30: 11.74 | F30: 12.57 | G30: 3.32 | I30: 2.23 | J30: 3.32
B31: k | C31: =IF(OR(C29="",C30=""),"",C30/C29) -> 1.6515625 | D31: =IF(OR(D29="",D30=""),"",D30/D29) -> 1.6541471 | E31: =IF(OR(E29="",E30=""),"",E30/E29) -> 1.6535211 | F31: =IF(OR(F29="",F30=""),"",F30/F29) -> 1.6474443 | G31: =IF(OR(G29="",G30=""),"",G30/G29) -> 1.4887892

Sheet Intevo Bold
A1: 16 cm phantom (Routine head)
B2: Collimation | C2: 4x0.6 | D2: 12x0.6 | E2: 16x0.6 | F2: 1x10 | G2: 12x1.2 | H2: 2x8 | I2: 16x1.2
B3: Total | C3: 2.4 | D3: 7.2 | E3: 9.6 | F3: 10 | G3: 14.4 | H3: 16 | I3: 19.2
B4: Acquisition | C4: 4x0.6 | D4: 12x0.6 | E4: 16x0.6 | F4: 1x10 | G4: 12x1.2 | H4: 2x8 | I4: 16x1.2
B5: Shaped filter
A6: kV
A7: 80 | B7: Center | C7: 7.6 | D7: 7.7 | E7: 6.64 | F7: 5.55 | G7: 6.04 | H7: 5.43 | I7: 6.13
B8: CTDIw | C8: 8.12 | D8: 8.2 | E8: 7.19 | F8: 5.9 | G8: 6.45 | H8: 5.81 | I8: 6.56
B9: k | C9: =IF(OR(C7="",C8=""),"",C8/C7) -> 1.0684211 | D9: =IF(OR(D7="",D8=""),"",D8/D7) -> 1.0649351 | E9: =IF(OR(E7="",E8=""),"",E8/E7) -> 1.0828313 | F9: =IF(OR(F7="",F8=""),"",F8/F7) -> 1.0630631 | G9: =IF(OR(G7="",G8=""),"",G8/G7) -> 1.0678808 | H9: =IF(OR(H7="",H8=""),"",H8/H7) -> 1.0699816 | I9: =IF(OR(I7="",I8=""),"",I8/I7) -> 1.0701468
A10: 110 | B10: Center | C10: 18 | D10: 17.63 | E10: 15.57 | F10: 12.69 | G10: 13.88 | H10: 12.49 | I10: 14.14
B11: CTDIw | C11: 18.65 | D11: 18.31 | E11: 16.18 | F11: 13.18 | G11: 14.43 | H11: 12.99 | I11: 14.7
B12: k | C12: =IF(OR(C10="",C11=""),"",C11/C10) -> 1.0361111 | D12: =IF(OR(D10="",D11=""),"",D11/D10) -> 1.0385706 | E12: =IF(OR(E10="",E11=""),"",E11/E10) -> 1.0391779 | F12: =IF(OR(F10="",F11=""),"",F11/F10) -> 1.0386131 | G12: =IF(OR(G10="",G11=""),"",G11/G10) -> 1.0396254 | H12: =IF(OR(H10="",H11=""),"",H11/H10) -> 1.040032 | I12: =IF(OR(I10="",I11=""),"",I11/I10) -> 1.039604
A13: 130 | B13: Center | C13: 25.78 | D13: 25.93 | E13: 22.91 | F13: 18.67 | G13: 20.42 | H13: 18.38 | I13: 20.81
B14: CTDIw | C14: 26.52 | D14: 26.72 | E14: 23.62 | F14: 19.24 | G14: 21.05 | H14: 18.94 | I14: 21.45
B15: k | C15: =IF(OR(C13="",C14=""),"",C14/C13) -> 1.0287044 | D15: =IF(OR(D13="",D14=""),"",D14/D13) -> 1.0304666 | E15: =IF(OR(E13="",E14=""),"",E14/E13) -> 1.0309908 | F15: =IF(OR(F13="",F14=""),"",F14/F13) -> 1.0305303 | G15: =IF(OR(G13="",G14=""),"",G14/G13) -> 1.0308521 | H15: =IF(OR(H13="",H14=""),"",H14/H13) -> 1.0304679 | I15: =IF(OR(I13="",I14=""),"",I14/I13) -> 1.0307544
A17: 32 cm phantom (Adult body)
B18: Collimation | C18: 4x0.6 | D18: 12x0.6 | E18: 16x0.6 | F18: 1x10 | G18: 12x1.2 | H18: 2x8 | I18: 16x1.2
B19: Total | C19: 2.4 | D19: 7.2 | E19: 9.6 | F19: 10 | G19: 14.4 | H19: 16 | I19: 19.2
B20: Acquisition | C20: 4x0.6 | D20: 12x0.6 | E20: 16x0.6 | F20: 1x10 | G20: 12x1.2 | H20: 2x8 | I20: 16x1.2
B21: Shaped filter
A22: kV
A23: 80 | B23: Center | C23: 1.88 | D23: 1.9 | E23: 1.68 | F23: 1.37 | G23: 1.5 | H23: 1.35 | I23: 1.52
B24: CTDIw | C24: 3.49 | D24: 3.54 | E24: 3.12 | F24: 2.55 | G24: 2.78 | H24: 2.5 | I24: 2.9
B25: k | C25: =IF(OR(C23="",C24=""),"",C24/C23) -> 1.856383 | D25: =IF(OR(D23="",D24=""),"",D24/D23) -> 1.8631579 | E25: =IF(OR(E23="",E24=""),"",E24/E23) -> 1.8571429 | F25: =IF(OR(F23="",F24=""),"",F24/F23) -> 1.8613139 | G25: =IF(OR(G23="",G24=""),"",G24/G23) -> 1.8533333 | H25: =IF(OR(H23="",H24=""),"",H24/H23) -> 1.8518519 | I25: =IF(OR(I23="",I24=""),"",I24/I23) -> 1.9078947
A26: 110 | B26: Center | C26: 5.24 | D26: 5.12 | E26: 4.52 | F26: 3.68 | G26: 4.05 | H26: 3.64 | I26: 4.12
B27: CTDIw | C27: 8.63 | D27: 8.5 | E27: 7.51 | F27: 6.12 | G27: 6.69 | H27: 6.02 | I27: 6.82
B28: k | C28: =IF(OR(C26="",C27=""),"",C27/C26) -> 1.6469466 | D28: =IF(OR(D26="",D27=""),"",D27/D26) -> 1.6601562 | E28: =IF(OR(E26="",E27=""),"",E27/E26) -> 1.6615044 | F28: =IF(OR(F26="",F27=""),"",F27/F26) -> 1.6630435 | G28: =IF(OR(G26="",G27=""),"",G27/G26) -> 1.6518519 | H28: =IF(OR(H26="",H27=""),"",H27/H26) -> 1.6538462 | I28: =IF(OR(I26="",I27=""),"",I27/I26) -> 1.6553398
A29: 130 | B29: Center | C29: 7.95 | D29: 8.02 | E29: 7.09 | F29: 5.78 | G29: 6.31 | H29: 5.68 | I29: 6.41
B30: CTDIw | C30: 12.63 | D30: 12.79 | E30: 11.29 | F30: 9.21 | G30: 10.04 | H30: 9.04 | I30: 10.21
B31: k | C31: =IF(OR(C29="",C30=""),"",C30/C29) -> 1.5886792 | D31: =IF(OR(D29="",D30=""),"",D30/D29) -> 1.5947631 | E31: =IF(OR(E29="",E30=""),"",E30/E29) -> 1.5923836 | F31: =IF(OR(F29="",F30=""),"",F30/F29) -> 1.5934256 | G31: =IF(OR(G29="",G30=""),"",G30/G29) -> 1.5911252 | H31: =IF(OR(H29="",H30=""),"",H30/H29) -> 1.5915493 | I31: =IF(OR(I29="",I30=""),"",I30/I29) -> 1.5928237

Sheet Biograph Vision
A1: 16 cm phantom, Standard shaped filter (Routine head)
B2: Collimation | C2: 2x1 | D2: 6x0.6 | E2: 8x0.6 | F2: 8x0.6 | G2: 1x5 | H2: 10x0.6 | I2: 6x1.2 | J2: 1x10 | K2: 20x0.6 | L2: 12x1.2 | M2: 64x0.6 | N2: 64x0.6
B3: Total | C3: 2 | D3: 3.6 | E3: 4.8 | F3: 4.8 | G3: 5 | H3: 6 | I3: 7.2 | J3: 10 | K3: 12 | L3: 14.4 | M3: 19.2 | N3: 38.4
B4: Acquisition | C4: 2x1 | D4: 6x0.6 | E4: 8x0.6 | F4: 16x0.6 | G4: 1x5 | H4: 20x0.6 | I4: 6x1.2 | J4: 1x10 | K4: 40x0.6 | L4: 12x1.2 | M4: 32x1.2 | N4: 128x0.6
D5: Topogram | E5: UHR | F5: UHR, z-sharp | H5: z-sharp | K5: z-sharp | N5: z-sharp
A6: kV
A7: 70 | B7: Center | C7: 2.6 | D7: 4.22 | E7: 3.88 | F7: 4.58 | G7: 2.34 | H7: 3.17 | I7: 3.3 | J7: 2.34 | K7: 3.23 | L7: 3 | M7: 3.01 | N7: 2.87
B8: CTDIw | C8: 2.74 | D8: 4.43 | E8: 4.07 | F8: 4.78 | G8: 2.46 | H8: 3.31 | I8: 3.35 | J8: 2.46 | K8: 3.38 | L8: 3.15 | M8: 3.15 | N8: 3.01
B9: k | C9: =IF(OR(C7="",C8=""),"",C8/C7) -> 1.0538462 | D9: =IF(OR(D7="",D8=""),"",D8/D7) -> 1.049763 | E9: =IF(OR(E7="",E8=""),"",E8/E7) -> 1.0489691 | F9: =IF(OR(F7="",F8=""),"",F8/F7) -> 1.0436681 | G9: =IF(OR(G7="",G8=""),"",G8/G7) -> 1.0512821 | H9: =IF(OR(H7="",H8=""),"",H8/H7) -> 1.044164 | I9: =IF(OR(I7="",I8=""),"",I8/I7) -> 1.0151515 | J9: =IF(OR(J7="",J8=""),"",J8/J7) -> 1.0512821 | ... N9: =IF(OR(N7="",N8=""),"",N8/N7) -> 1.0487805
A10: 80 | B10: Center | C10: 4.18 | D10: 6.76 | E10: 6.22 | F10: 7.24 | G10: 3.75 | H10: 5.02 | I10: 5.39 | J10: 3.75 | K10: 5.12 | L10: 4.81 | M10: 4.77 | N10: 4.6
B11: CTDIw | C11: 4.36 | D11: 7.06 | E11: 6.49 | F11: 7.46 | G11: 3.91 | H11: 5.17 | I11: 5.62 | J11: 3.91 | K11: 5.27 | L11: 5.02 | M11: 4.91 | N11: 4.8
B12: k | C12: =IF(OR(C10="",C11=""),"",C11/C10) -> 1.0430622 | D12: =IF(OR(D10="",D11=""),"",D11/D10) -> 1.0443787 | E12: =IF(OR(E10="",E11=""),"",E11/E10) -> 1.0434084 | F12: =IF(OR(F10="",F11=""),"",F11/F10) -> 1.0303867 | G12: =IF(OR(G10="",G11=""),"",G11/G10) -> 1.0426667 | H12: =IF(OR(H10="",H11=""),"",H11/H10) -> 1.0298805 | I12: =IF(OR(I10="",I11=""),"",I11/I10) -> 1.0426716 | J12: =IF(OR(J10="",J11=""),"",J11/J10) -> 1.0426667 | ... N12: =IF(OR(N10="",N11=""),"",N11/N10) -> 1.0434783
A13: 100 | B13: Center | C13: 8.44 | D13: 13.67 | E13: 12.56 | F13: 14.69 | G13: 7.57 | H13: 10.19 | I13: 10.89 | J13: 7.57 | K13: 10.38 | L13: 9.71 | M13: 8.48 | N13: 8.57
B14: CTDIw | C14: 8.65 | D14: 14.01 | E14: 12.88 | F14: 14.93 | G14: 7.76 | H14: 10.35 | I14: 11.16 | J14: 7.76 | K14: 10.55 | L14: 9.96 | M14: 8.69 | N14: 8.71
B15: k | C15: =IF(OR(C13="",C14=""),"",C14/C13) -> 1.0248815 | D15: =IF(OR(D13="",D14=""),"",D14/D13) -> 1.024872 | E15: =IF(OR(E13="",E14=""),"",E14/E13) -> 1.0254777 | F15: =IF(OR(F13="",F14=""),"",F14/F13) -> 1.0163376 | G15: =IF(OR(G13="",G14=""),"",G14/G13) -> 1.0250991 | H15: =IF(OR(H13="",H14=""),"",H14/H13) -> 1.0157017 | I15: =IF(OR(I13="",I14=""),"",I14/I13) -> 1.0247934 | J15: =IF(OR(J13="",J14=""),"",J14/J13) -> 1.0250991 | ... N15: =IF(OR(N13="",N14=""),"",N14/N13) -> 1.0163361
A16: 120 | B16: Center | C16: 13.85 | D16: 22.42 | E16: 20.6 | F16: 24.33 | G16: 12.42 | H16: 16.87 | I16: 17.86 | J16: 12.42 | K16: 17.19 | L16: 15.93 | M16: 13.91 | N16: 14.19
B17: CTDIw | C17: 14.11 | D17: 22.85 | E17: 21 | F17: 24.63 | G17: 12.66 | H17: 17.08 | I17: 18.2 | J17: 12.66 | K17: 17.41 | L17: 16.24 | M17: 14.17 | N17: 14.37
B18: k | C18: =IF(OR(C16="",C17=""),"",C17/C16) -> 1.0187726 | D18: =IF(OR(D16="",D17=""),"",D17/D16) -> 1.0191793 | E18: =IF(OR(E16="",E17=""),"",E17/E16) -> 1.0194175 | F18: =IF(OR(F16="",F17=""),"",F17/F16) -> 1.0123305 | G18: =IF(OR(G16="",G17=""),"",G17/G16) -> 1.0193237 | H18: =IF(OR(H16="",H17=""),"",H17/H16) -> 1.0124481 | I18: =IF(OR(I16="",I17=""),"",I17/I16) -> 1.019037 | J18: =IF(OR(J16="",J17=""),"",J17/J16) -> 1.0193237 | ... N18: =IF(OR(N16="",N17=""),"",N17/N16) -> 1.012685
A19: 140 | B19: Center | C19: 20.24 | D19: 32.77 | E19: 30.12 | F19: 36.16 | G19: 18.16 | H19: 25.07 | I19: 26.11 | J19: 18.16 | K19: 25.55 | L19: 23.3 | M19: 20.33 | N19: 21.09
B20: CTDIw | C20: 20.6 | D20: 33.35 | E20: 30.65 | F20: 36.6 | G20: 18.48 | H20: 25.4 | I20: 26.56 | J20: 18.48 | K20: 25.89 | L20: 23.7 | M20: 20.69 | N20: 21.37
B21: k | C21: =IF(OR(C19="",C20=""),"",C20/C19) -> 1.0177866 | D21: =IF(OR(D19="",D20=""),"",D20/D19) -> 1.0176991 | E21: =IF(OR(E19="",E20=""),"",E20/E19) -> 1.0175963 | F21: =IF(OR(F19="",F20=""),"",F20/F19) -> 1.0121681 | G21: =IF(OR(G19="",G20=""),"",G20/G19) -> 1.0176211 | H21: =IF(OR(H19="",H20=""),"",H20/H19) -> 1.0131631 | I21: =IF(OR(I19="",I20=""),"",I20/I19) -> 1.0172348 | J21: =IF(OR(J19="",J20=""),"",J20/J19) -> 1.0176211 | ... N21: =IF(OR(N19="",N20=""),"",N20/N19) -> 1.0132764
A23: 16 cm phantom, Narrow shaped filter (Pediatric body)
B24: Collimation | C24: 2x1 | D24: 6x0.6 | E24: 8x0.6 | F24: 8x0.6 | G24: 1x5 | H24: 10x0.6 | I24: 6x1.2 | J24: 1x10 | K24: 20x0.6 | L24: 12x1.2 | M24: 32x0.6 | N24: 64x0.6
B25: Total | C25: 2 | D25: 3.6 | E25: 4.8 | F25: 4.8 | G25: 5 | H25: 6 | I25: 7.2 | J25: 10 | K25: 12 | L25: 14.4 | M25: 38.4 | N25: 38.4
B26: Acquisition | C26: 2x1 | D26: 6x0.6 | E26: 8x0.6 | F26: 16x0.6 | G26: 1x5 | H26: 20x0.6 | I26: 6x1.2 | J26: 1x10 | K26: 40x0.6 | L26: 12x1.2 | M26: 32x1.2 | N26: 28.x.6
B27: Shaped filter | F27: z-sharp | H27: z-sharp | K27: z-sharp | N27: z-sharp
A28: kV
A29: 70 | B29: Center | C29: 2.36 | D29: 3.83 | E29: 3.52 | F29: 4.12 | G29: 2.12 | H29: 2.86 | I29: 3.05 | J29: 2.12 | K29: 2.91 | L29: 2.72 | M29: 2.38 | N29: 2.4
B30: CTDIw | C30: 2.36 | D30: 3.81 | E30: 3.51 | F30: 4.07 | G30: 2.11 | H30: 2.82 | I30: 3.04 | J30: 2.11 | K30: 2.88 | L30: 2.71 | M30: 2.37 | N30: 2.37
B31: k | C31: =IF(OR(C29="",C30=""),"",C30/C29) -> 1 | D31: =IF(OR(D29="",D30=""),"",D30/D29) -> 0.99477807 | E31: =IF(OR(E29="",E30=""),"",E30/E29) -> 0.99715909 | F31: =IF(OR(F29="",F30=""),"",F30/F29) -> 0.98786408 | G31: =IF(OR(G29="",G30=""),"",G30/G29) -> 0.99528302 | H31: =IF(OR(H29="",H30=""),"",H30/H29) -> 0.98601399 | I31: =IF(OR(I29="",I30=""),"",I30/I29) -> 0.99672131 | J31: =IF(OR(J29="",J30=""),"",J30/J29) -> 0.99528302 | ... N31: =IF(OR(N29="",N30=""),"",N30/N29) -> 0.9875
A32: 80 | B32: Center | C32: 3.81 | D32: 6.17 | E32: 5.67 | F32: 6.58 | G32: 3.42 | H32: 4.56 | I32: 4.92 | J32: 3.42 | K32: 4.65 | L32: 4.39 | M32: 3.83 | N32: 3.84
B33: CTDIw | C33: 3.78 | D33: 6.12 | E33: 5.63 | F33: 6.44 | G33: 3.39 | H33: 4.47 | I33: 4.88 | J33: 3.39 | K33: 4.55 | L33: 4.35 | M33: 3.8 | N33: 3.76
B34: k | C34: =IF(OR(C32="",C33=""),"",C33/C32) -> 0.99212598 | D34: =IF(OR(D32="",D33=""),"",D33/D32) -> 0.99189627 | E34: =IF(OR(E32="",E33=""),"",E33/E32) -> 0.99294533 | F34: =IF(OR(F32="",F33=""),"",F33/F32) -> 0.9787234 | G34: =IF(OR(G32="",G33=""),"",G33/G32) -> 0.99122807 | H34: =IF(OR(H32="",H33=""),"",H33/H32) -> 0.98026316 | I34: =IF(OR(I32="",I33=""),"",I33/I32) -> 0.99186992 | J34: =IF(OR(J32="",J33=""),"",J33/J32) -> 0.99122807 | ... N34: =IF(OR(N32="",N33=""),"",N33/N32) -> 0.97916667
A35: 100 | B35: Center | C35: 7.81 | D35: 12.65 | E35: 11.63 | F35: 13.53 | G35: 7.01 | H35: 9.38 | I35: 10.08 | J35: 7.01 | K35: 9.56 | L35: 8.99 | M35: 7.85 | N35: 7.89
B36: CTDIw | C36: 7.69 | D36: 12.45 | E36: 11.44 | F36: 13.14 | G36: 6.9 | H36: 9.11 | I36: 9.92 | J36: 6.9 | K36: 9.29 | L36: 8.85 | M36: 7.72 | N36: 7.67
B37: k | C37: =IF(OR(C35="",C36=""),"",C36/C35) -> 0.98463508 | D37: =IF(OR(D35="",D36=""),"",D36/D35) -> 0.98418972 | E37: =IF(OR(E35="",E36=""),"",E36/E35) -> 0.98366294 | F37: =IF(OR(F35="",F36=""),"",F36/F35) -> 0.97117517 | G37: =IF(OR(G35="",G36=""),"",G36/G35) -> 0.98430813 | H37: =IF(OR(H35="",H36=""),"",H36/H35) -> 0.97121535 | I37: =IF(OR(I35="",I36=""),"",I36/I35) -> 0.98412698 | J37: =IF(OR(J35="",J36=""),"",J36/J35) -> 0.98430813 | ... N37: =IF(OR(N35="",N36=""),"",N36/N35) -> 0.9721166
A38: 120 | B38: Center | C38: 12.93 | D38: 20.93 | E38: 19.23 | F38: 22.53 | G38: 11.6 | H38: 15.62 | I38: 16.67 | J38: 11.6 | K38: 15.92 | L38: 14.87 | M38: 12.98 | N38: 13.14
B39: CTDIw | C39: 12.68 | D39: 20.52 | E39: 18.86 | F39: 21.91 | G39: 11.37 | H39: 15.19 | I39: 16.35 | J39: 11.37 | K39: 15.48 | L39: 14.59 | M39: 12.73 | N39: 12.78
B40: k | C40: =IF(OR(C38="",C39=""),"",C39/C38) -> 0.98066512 | D40: =IF(OR(D38="",D39=""),"",D39/D38) -> 0.98041089 | E40: =IF(OR(E38="",E39=""),"",E39/E38) -> 0.98075923 | F40: =IF(OR(F38="",F39=""),"",F39/F38) -> 0.97248114 | G40: =IF(OR(G38="",G39=""),"",G39/G38) -> 0.98017241 | H40: =IF(OR(H38="",H39=""),"",H39/H38) -> 0.97247119 | I40: =IF(OR(I38="",I39=""),"",I39/I38) -> 0.98080384 | J40: =IF(OR(J38="",J39=""),"",J39/J38) -> 0.98017241 | ... N40: =IF(OR(N38="",N39=""),"",N39/N38) -> 0.97260274
A41: 140 | B41: Center | C41: 18.83 | D41: 30.49 | E41: 28.02 | F41: 33.71 | G41: 16.89 | H41: 23.38 | I41: 24.29 | J41: 16.89 | K41: 23.82 | L41: 21.67 | M41: 18.91 | N41: 19.67
...

Sheet X.cite
A1: 16 cm phantom, Standard shaped filter (Routine head)
B2: Collimation | C2: 6x0.6 | D2: 1x5 | E2: 1x10 | F2: 3x3 | G2: 3x5 | H2: 64x0.6 | I2: 64x0.6 | J2: 128x0.6
B3: Acquisition | C3: 6x0.6 | D3: 1x5 | E3: 1x10 | F3: 3x3 | G3: 3x5 | H3: 32x0.6 | I3: 64x0.6 | J3: 64x0.6
A4: kV
A5: 70 | B5: Center | E5: 3.16 | H5: 4.47 | I5: 3.93 | J5: 3.91
B6: CTDIw | E6: 3.4 | H6: 4.8 | I6: 4.24 | J6: 4.21
B7: k | C7: =IF(OR(C5="",C6=""),"",C6/C5) | D7: =IF(OR(D5="",D6=""),"",D6/D5) | E7: =IF(OR(E5="",E6=""),"",E6/E5) -> 1.0759494 | F7: =IF(OR(F5="",F6=""),"",F6/F5) | G7: =IF(OR(G5="",G6=""),"",G6/G5) | H7: =IF(OR(H5="",H6=""),"",H6/H5) -> 1.0738255 | I7: =IF(OR(I5="",I6=""),"",I6/I5) -> 1.0788804 | J7: =IF(OR(J5="",J6=""),"",J6/J5) -> 1.0767263
A8: 80 | B8: Center | E8: 4.87 | H8: 6.88 | I8: 6.05 | J8: 6.02
B9: CTDIw | E9: 5.14 | H9: 7.25 | I9: 6.42 | J9: 6.37
B10: k | C10: =IF(OR(C8="",C9=""),"",C9/C8) | D10: =IF(OR(D8="",D9=""),"",D9/D8) | E10: =IF(OR(E8="",E9=""),"",E9/E8) -> 1.0554415 | F10: =IF(OR(F8="",F9=""),"",F9/F8) | G10: =IF(OR(G8="",G9=""),"",G9/G8) | H10: =IF(OR(H8="",H9=""),"",H9/H8) -> 1.0537791 | I10: =IF(OR(I8="",I9=""),"",I9/I8) -> 1.061157 | J10: =IF(OR(J8="",J9=""),"",J9/J8) -> 1.0581395
A11: 90 | B11: Center | E11: 6.88 | H11: 9.73 | I11: 8.56 | J11: 8.52
B12: CTDIw | E12: 7.19 | H12: 10.15 | I12: 8.97 | J12: 8.9
B13: k | C13: =IF(OR(C11="",C12=""),"",C12/C11) | D13: =IF(OR(D11="",D12=""),"",D12/D11) | E13: =IF(OR(E11="",E12=""),"",E12/E11) -> 1.0450581 | F13: =IF(OR(F11="",F12=""),"",F12/F11) | G13: =IF(OR(G11="",G12=""),"",G12/G11) | H13: =IF(OR(H11="",H12=""),"",H12/H11) -> 1.0431655 | I13: =IF(OR(I11="",I12=""),"",I12/I11) -> 1.0478972 | J13: =IF(OR(J11="",J12=""),"",J12/J11) -> 1.0446009
A14: 100 | B14: Center | E14: 9.15 | H14: 12.95 | I14: 11.38 | J14: 11.33
B15: CTDIw | E15: 9.49 | H15: 13.39 | I15: 11.84 | J15: 11.75
B16: k | C16: =IF(OR(C14="",C15=""),"",C15/C14) | D16: =IF(OR(D14="",D15=""),"",D15/D14) | E16: =IF(OR(E14="",E15=""),"",E15/E14) -> 1.0371585 | F16: =IF(OR(F14="",F15=""),"",F15/F14) | G16: =IF(OR(G14="",G15=""),"",G15/G14) | H16: =IF(OR(H14="",H15=""),"",H15/H14) -> 1.0339768 | I16: =IF(OR(I14="",I15=""),"",I15/I14) -> 1.0404218 | J16: =IF(OR(J14="",J15=""),"",J15/J14) -> 1.0370697
A17: 110 | B17: Center | E17: 11.63 | H17: 16.45 | I17: 14.46 | J17: 14.4
B18: CTDIw | E18: 12.01 | H18: 16.94 | I18: 14.98 | J18: 14.86
B19: k | C19: =IF(OR(C17="",C18=""),"",C18/C17) | D19: =IF(OR(D17="",D18=""),"",D18/D17) | E19: =IF(OR(E17="",E18=""),"",E18/E17) -> 1.0326741 | F19: =IF(OR(F17="",F18=""),"",F18/F17) | G19: =IF(OR(G17="",G18=""),"",G18/G17) | H19: =IF(OR(H17="",H18=""),"",H18/H17) -> 1.0297872 | I19: =IF(OR(I17="",I18=""),"",I18/I17) -> 1.0359613 | J19: =IF(OR(J17="",J18=""),"",J18/J17) -> 1.0319444
A20: 120 | B20: Center | E20: 14.33 | H20: 20.26 | I20: 17.81 | J20: 17.73
B21: CTDIw | E21: 14.71 | H21: 20.75 | I21: 18.36 | J21: 18.21
B22: k | C22: =IF(OR(C20="",C21=""),"",C21/C20) | D22: =IF(OR(D20="",D21=""),"",D21/D20) | E22: =IF(OR(E20="",E21=""),"",E21/E20) -> 1.0265178 | F22: =IF(OR(F20="",F21=""),"",F21/F20) | G22: =IF(OR(G20="",G21=""),"",G21/G20) | H22: =IF(OR(H20="",H21=""),"",H21/H20) -> 1.0241856 | I22: =IF(OR(I20="",I21=""),"",I21/I20) -> 1.0308815 | J22: =IF(OR(J20="",J21=""),"",J21/J20) -> 1.0270728
A23: 130 | B23: Center | E23: 17.15 | H23: 24.27 | I23: 21.33 | J23: 21.24
B24: CTDIw | E24: 17.6 | H24: 24.83 | I24: 21.96 | J24: 21.79
B25: k | C25: =IF(OR(C23="",C24=""),"",C24/C23) | D25: =IF(OR(D23="",D24=""),"",D24/D23) | E25: =IF(OR(E23="",E24=""),"",E24/E23) -> 1.0262391 | F25: =IF(OR(F23="",F24=""),"",F24/F23) | G25: =IF(OR(G23="",G24=""),"",G24/G23) | H25: =IF(OR(H23="",H24=""),"",H24/H23) -> 1.0230738 | I25: =IF(OR(I23="",I24=""),"",I24/I23) -> 1.0295359 | J25: =IF(OR(J23="",J24=""),"",J24/J23) -> 1.0258945
A26: 140 | B26: Center | E26: 20.15 | H26: 28.51 | I26: 25.06 | J26: 24.95
B27: CTDIw | E27: 20.65 | H27: 29.14 | I27: 25.77 | J27: 25.57
B28: k | C28: =IF(OR(C26="",C27=""),"",C27/C26) | D28: =IF(OR(D26="",D27=""),"",D27/D26) | E28: =IF(OR(E26="",E27=""),"",E27/E26) -> 1.0248139 | F28: =IF(OR(F26="",F27=""),"",F27/F26) | G28: =IF(OR(G26="",G27=""),"",G27/G26) | H28: =IF(OR(H26="",H27=""),"",H27/H26) -> 1.0220975 | I28: =IF(OR(I26="",I27=""),"",I27/I26) -> 1.028332 | J28: =IF(OR(J26="",J27=""),"",J27/J26) -> 1.0248497
A29: 150 | B29: Center | E29: 23.36 | H29: 33.04 | I29: 29.05 | J29: 28.92
B30: CTDIw | E30: 23.89 | H30: 33.7 | I30: 29.81 | J30: 29.57
B31: k | C31: =IF(OR(C29="",C30=""),"",C30/C29) | D31: =IF(OR(D29="",D30=""),"",D30/D29) | E31: =IF(OR(E29="",E30=""),"",E30/E29) -> 1.0226884 | F31: =IF(OR(F29="",F30=""),"",F30/F29) | G31: =IF(OR(G29="",G30=""),"",G30/G29) | H31: =IF(OR(H29="",H30=""),"",H30/H29) -> 1.0199758 | I31: =IF(OR(I29="",I30=""),"",I30/I29) -> 1.0261618 | J31: =IF(OR(J29="",J30=""),"",J30/J29) -> 1.0224758
A32: 100SnLD | B32: Center | C32: 2.7 | H32: 2.08 | I32: 1.83 | J32: 1.82
B33: CTDIw | C33: 2.69 | H33: 2.08 | I33: 1.84 | J33: 1.83
B34: k | C34: =IF(OR(C32="",C33=""),"",C33/C32) -> 0.9962963 | D34: =IF(OR(D32="",D33=""),"",D33/D32) | E34: =IF(OR(E32="",E33=""),"",E33/E32) | F34: =IF(OR(F32="",F33=""),"",F33/F32) | G34: =IF(OR(G32="",G33=""),"",G33/G32) | H34: =IF(OR(H32="",H33=""),"",H33/H32) -> 1 | I34: =IF(OR(I32="",I33=""),"",I33/I32) -> 1.0054645 | J34: =IF(OR(J32="",J33=""),"",J33/J32) -> 1.0054945
A35: 110SnLD | B35: Center | H35: 3.19 | I35: 2.8 | J35: 2.79
B36: CTDIw | H36: 3.18 | I36: 2.821 | J36: 2.8
B37: k | C37: =IF(OR(C35="",C36=""),"",C36/C35) | D37: =IF(OR(D35="",D36=""),"",D36/D35) | E37: =IF(OR(E35="",E36=""),"",E36/E35) | F37: =IF(OR(F35="",F36=""),"",F36/F35) | G37: =IF(OR(G35="",G36=""),"",G36/G35) | H37: =IF(OR(H35="",H36=""),"",H36/H35) -> 0.9968652 | I37: =IF(OR(I35="",I36=""),"",I36/I35) -> 1.0075 | J37: =IF(OR(J35="",J36=""),"",J36/J35) -> 1.0035842
A38: 120SnLD | B38: Center | H38: 4.55 | I38: 4 | J38: 3.97
B39: CTDIw | H39: 4.55 | I39: 4.03 | J39: 4
B40: k | C40: =IF(OR(C38="",C39=""),"",C39/C38) | D40: =IF(OR(D38="",D39=""),"",D39/D38) | E40: =IF(OR(E38="",E39=""),"",E39/E38) | F40: =IF(OR(F38="",F39=""),"",F39/F38) | G40: =IF(OR(G38="",G39=""),"",G39/G38) | H40: =IF(OR(H38="",H39=""),"",H39/H38) -> 1 | I40: =IF(OR(I38="",I39=""),"",I39/I38) -> 1.0075 | J40: =IF(OR(J38="",J39=""),"",J39/J38) -> 1.0075567
...

Sheet Confidence 20
A1: 16 cm phantom, Standard shaped filter (Routine head)
B2: Collimation | C2: 2x1 | D2: 1x5 | E2: 10x0.6 | F2: 6x1.2 | G2: 1x10 | H2: 20x0.6 | I2: 12x1.2 | J2: 16x1.2
B3: Total | C3: 2 | D3: 5 | E3: 6 | F3: 7.2 | G3: 10 | H3: 12 | I3: 14.4 | J3: 19.2
B4: Acquisition | C4: 2x1 | D4: 1x5 | E4: 10x0.6 | F4: 6x1.2 | G4: 1x10 | H4: 20x0.6 | I4: 12x1.2 | J4: 16x1.2
A5: kV
A6: 70 | B6: Center | C6: 2.86 | D6: 2.57 | E6: 3.54 | F6: 3.69 | G6: 2.57 | H6: 3.48 | I6: 3.29 | J6: 3.15
B7: CTDIw | C7: 3.06 | D7: 2.74 | E7: 3.79 | F7: 3.94 | G7: 2.74 | H7: 3.71 | I7: 3.52 | J7: 3.37
B8: k | C8: =IF(OR(C6="",C7=""),"",C7/C6) -> 1.0699301 | D8: =IF(OR(D6="",D7=""),"",D7/D6) -> 1.0661479 | E8: =IF(OR(E6="",E7=""),"",E7/E6) -> 1.0706215 | F8: =IF(OR(F6="",F7=""),"",F7/F6) -> 1.0677507 | G8: =IF(OR(G6="",G7=""),"",G7/G6) -> 1.0661479 | H8: =IF(OR(H6="",H7=""),"",H7/H6) -> 1.066092 | I8: =IF(OR(I6="",I7=""),"",I7/I6) -> 1.0699088 | J8: =IF(OR(J6="",J7=""),"",J7/J6) -> 1.0698413
A9: 80 | B9: Center | C9: 4.57 | D9: 4.1 | E9: 5.65 | F9: 5.89 | G9: 4.1 | H9: 5.54 | I9: 5.25 | J9: 5.03
B10: CTDIw | C10: 4.77 | D10: 4.28 | E10: 5.91 | F10: 6.16 | G10: 4.28 | H10: 5.8 | I10: 5.49 | J10: 5.26
B11: k | C11: =IF(OR(C9="",C10=""),"",C10/C9) -> 1.0437637 | D11: =IF(OR(D9="",D10=""),"",D10/D9) -> 1.0439024 | E11: =IF(OR(E9="",E10=""),"",E10/E9) -> 1.0460177 | F11: =IF(OR(F9="",F10=""),"",F10/F9) -> 1.0458404 | G11: =IF(OR(G9="",G10=""),"",G10/G9) -> 1.0439024 | H11: =IF(OR(H9="",H10=""),"",H10/H9) -> 1.0469314 | I11: =IF(OR(I9="",I10=""),"",I10/I9) -> 1.0457143 | J11: =IF(OR(J9="",J10=""),"",J10/J9) -> 1.0457256
A12: 100 | B12: Center | C12: 8.84 | D12: 7.93 | E12: 10.94 | F12: 11.4 | G12: 7.93 | H12: 10.73 | I12: 10.17 | J12: 9.73
B13: CTDIw | C13: 9.02 | D13: 8.1 | E13: 11.17 | F13: 11.64 | G13: 8.1 | H13: 10.96 | I13: 10.39 | J13: 9.94
B14: k | C14: =IF(OR(C12="",C13=""),"",C13/C12) -> 1.020362 | D14: =IF(OR(D12="",D13=""),"",D13/D12) -> 1.0214376 | E14: =IF(OR(E12="",E13=""),"",E13/E12) -> 1.0210238 | F14: =IF(OR(F12="",F13=""),"",F13/F12) -> 1.0210526 | G14: =IF(OR(G12="",G13=""),"",G13/G12) -> 1.0214376 | H14: =IF(OR(H12="",H13=""),"",H13/H12) -> 1.0214352 | I14: =IF(OR(I12="",I13=""),"",I13/I12) -> 1.0216323 | J14: =IF(OR(J12="",J13=""),"",J13/J12) -> 1.0215827
A15: 120 | B15: Center | C15: 14.89 | D15: 13.36 | E15: 18.44 | F15: 19.21 | G15: 13.36 | H15: 18.08 | I15: 17.14 | J15: 16.4
B16: CTDIw | C16: 15.07 | D16: 13.52 | E16: 18.66 | F16: 19.43 | G16: 13.52 | H16: 18.3 | I16: 17.34 | J16: 16.59
B17: k | C17: =IF(OR(C15="",C16=""),"",C16/C15) -> 1.0120887 | D17: =IF(OR(D15="",D16=""),"",D16/D15) -> 1.011976 | E17: =IF(OR(E15="",E16=""),"",E16/E15) -> 1.0119306 | F17: =IF(OR(F15="",F16=""),"",F16/F15) -> 1.0114524 | G17: =IF(OR(G15="",G16=""),"",G16/G15) -> 1.011976 | H17: =IF(OR(H15="",H16=""),"",H16/H15) -> 1.0121681 | I17: =IF(OR(I15="",I16=""),"",I16/I15) -> 1.0116686 | J17: =IF(OR(J15="",J16=""),"",J16/J15) -> 1.0115854
A18: 140 | B18: Center | C18: 21.22 | D18: 19.04 | E18: 26.27 | F18: 27.37 | G18: 19.04 | H18: 25.77 | I18: 24.42 | J18: 23.37
B19: CTDIw | C19: 21.38 | D19: 19.18 | E19: 26.47 | F19: 27.57 | G19: 19.18 | H19: 15.96 | I19: 24.6 | J19: 23.54
B20: k | C20: =IF(OR(C18="",C19=""),"",C19/C18) -> 1.0075401 | D20: =IF(OR(D18="",D19=""),"",D19/D18) -> 1.0073529 | E20: =IF(OR(E18="",E19=""),"",E19/E18) -> 1.0076132 | F20: =IF(OR(F18="",F19=""),"",F19/F18) -> 1.0073073 | G20: =IF(OR(G18="",G19=""),"",G19/G18) -> 1.0073529 | H20: =IF(OR(H18="",H19=""),"",H19/H18) -> 0.6193248 | I20: =IF(OR(I18="",I19=""),"",I19/I18) -> 1.007371 | J20: =IF(OR(J18="",J19=""),"",J19/J18) -> 1.0072743
A22: 16 cm phantom, Narrow shaped filter (Pediatric body)
B23: Collimation | C23: 2x1 | D23: 1x5 | E23: 10x0.6 | F23: 6x1.2 | G23: 1x10 | H23: 20x0.6 | I23: 12x1.2 | J23: 16x1.2
B24: Total | C24: 2 | D24: 5 | E24: 6 | F24: 7.2 | G24: 10 | H24: 12 | I24: 14.4 | J24: 19.2
B25: Acquisition | C25: 2x1 | D25: 1x5 | E25: 10x0.6 | F25: 6x1.2 | G25: 1x10 | H25: 20x0.6 | I25: 12x1.2 | J25: 16x1.2
A26: kV
A27: 70 | B27: Center | C27: 2.54 | D27: 2.28 | E27: 3.15 | F27: 3.28 | G27: 2.28 | H27: 3.09 | I27: 2.93 | J27: 2.8
B28: CTDIw | C28: 2.55 | D28: 2.28 | E28: 3.15 | F28: 3.28 | G28: 2.28 | H28: 3.09 | I28: 2.93 | J28: 2.8
B29: k | C29: =IF(OR(C27="",C28=""),"",C28/C27) -> 1.003937 | D29: =IF(OR(D27="",D28=""),"",D28/D27) -> 1 | E29: =IF(OR(E27="",E28=""),"",E28/E27) -> 1 | F29: =IF(OR(F27="",F28=""),"",F28/F27) -> 1 | G29: =IF(OR(G27="",G28=""),"",G28/G27) -> 1 | H29: =IF(OR(H27="",H28=""),"",H28/H27) -> 1 | I29: =IF(OR(I27="",I28=""),"",I28/I27) -> 1 | J29: =IF(OR(J27="",J28=""),"",J28/J27) -> 1
A30: 80 | B30: Center | C30: 4.11 | D30: 3.69 | E30: 5.09 | F30: 5.3 | G30: 3.69 | H30: 4.99 | I30: 4.73 | J30: 4.53
B31: CTDIw | C31: 4.05 | D31: 3.64 | E31: 5.02 | F31: 5.23 | G31: 3.64 | H31: 4.92 | I31: 4.66 | J31: 5.26
B32: k | C32: =IF(OR(C30="",C31=""),"",C31/C30) -> 0.98540146 | D32: =IF(OR(D30="",D31=""),"",D31/D30) -> 0.98644986 | E32: =IF(OR(E30="",E31=""),"",E31/E30) -> 0.98624754 | F32: =IF(OR(F30="",F31=""),"",F31/F30) -> 0.98679245 | G32: =IF(OR(G30="",G31=""),"",G31/G30) -> 0.98644986 | H32: =IF(OR(H30="",H31=""),"",H31/H30) -> 0.98597194 | I32: =IF(OR(I30="",I31=""),"",I31/I30) -> 0.98520085 | J32: =IF(OR(J30="",J31=""),"",J31/J30) -> 1.1611479
A33: 100 | B33: Center | C33: 8.04 | D33: 7.21 | E33: 9.95 | F33: 10.37 | G33: 7.21 | H33: 9.76 | I33: 9.25 | J33: 8.85
B34: CTDIw | C34: 7.82 | D34: 7.02 | E34: 9.68 | F34: 10.09 | G34: 7.02 | H34: 9.5 | I34: 9 | J34: 8.61
B35: k | C35: =IF(OR(C33="",C34=""),"",C34/C33) -> 0.97263682 | D35: =IF(OR(D33="",D34=""),"",D34/D33) -> 0.97364771 | E35: =IF(OR(E33="",E34=""),"",E34/E33) -> 0.97286432 | F35: =IF(OR(F33="",F34=""),"",F34/F33) -> 0.97299904 | G35: =IF(OR(G33="",G34=""),"",G34/G33) -> 0.97364771 | H35: =IF(OR(H33="",H34=""),"",H34/H33) -> 0.97336066 | I35: =IF(OR(I33="",I34=""),"",I34/I33) -> 0.97297297 | J35: =IF(OR(J33="",J34=""),"",J34/J33) -> 0.97288136
A36: 120 | B36: Center | C36: 11.68 | D36: 12.28 | E36: 16.94 | F36: 17.65 | G36: 12.28 | H36: 16.62 | I36: 15.75 | J36: 15.07
B37: CTDIw | C37: 13.28 | D37: 11.92 | E37: 16.44 | F37: 17.13 | G37: 11.92 | H37: 16.13 | I37: 15.28 | J37: 14.63
B38: k | C38: =IF(OR(C36="",C37=""),"",C37/C36) -> 1.1369863 | D38: =IF(OR(D36="",D37=""),"",D37/D36) -> 0.97068404 | E38: =IF(OR(E36="",E37=""),"",E37/E36) -> 0.97048406 | F38: =IF(OR(F36="",F37=""),"",F37/F36) -> 0.97053824 | G38: =IF(OR(G36="",G37=""),"",G37/G36) -> 0.97068404 | H38: =IF(OR(H36="",H37=""),"",H37/H36) -> 0.97051745 | I38: =IF(OR(I36="",I37=""),"",I37/I36) -> 0.97015873 | J38: =IF(OR(J36="",J37=""),"",J37/J36) -> 0.97080292
A39: 140 | B39: Center | C39: 19.6 | D39: 17.58 | E39: 24.27 | F39: 25.28 | G39: 17.58 | H39: 23.8 | I39: 22.56 | J39: 21.58
B40: CTDIw | C40: 19.01 | D40: 17.05 | E40: 23.53 | F40: 24.51 | G40: 17.05 | H40: 23.08 | I40: 21.87 | J40: 20.93
B41: k | C41: =IF(OR(C39="",C40=""),"",C40/C39) -> 0.96989796 | D41: =IF(OR(D39="",D40=""),"",D40/D39) -> 0.9698521 | E41: =IF(OR(E39="",E40=""),"",E40/E39) -> 0.96950968 | F41: =IF(OR(F39="",F40=""),"",F40/F39) -> 0.96954114 | G41: =IF(OR(G39="",G40=""),"",G40/G39) -> 0.9698521 | H41: =IF(OR(H39="",H40=""),"",H40/H39) -> 0.9697479 | I41: =IF(OR(I39="",I40=""),"",I40/I39) -> 0.96941489 | J41: =IF(OR(J39="",J40=""),"",J40/J39) -> 0.96987952
...

Sheet Confidence 64
A1: 16 cm phantom, Standard shaped filter (Routine head)
B2: Collimation | C2: 2x1 | D2: 1x5 | E2: 10x0.6 | F2: 6x1.2 | G2: 1x10 | H2: 20x0.6 | I2: 12x1.2 | J2: 32x0.6 | K2: 16x1.2
B3: Total | C3: 2 | D3: 5 | E3: 6 | F3: 7.2 | G3: 10 | H3: 12 | I3: 14.4 | J3: 19.2 | K3: 19.2
B4: Acquisition | C4: 2x1 | D4: 1x5 | E4: 20x0.6 | F4: 6x1.2 | G4: 1x10 | H4: 40x0.6 | I4: 12x1.2 | J4: 64x0.6 | K4: 16x1.2
A5: kV
A6: 70 | B6: Center | C6: 2.86 | D6: 2.57 | E6: 3.41 | F6: 3.69 | G6: 2.57 | H6: 3.48 | I6: 3.29 | J6: 3.24 | K6: 3.15
B7: CTDIw | C7: 3.06 | D7: 2.74 | E7: 3.63 | F7: 3.94 | G7: 2.74 | H7: 3.7 | I7: 3.52 | J7: 3.44 | K7: 3.37
B8: k | C8: =IF(OR(C6="",C7=""),"",C7/C6) -> 1.0699301 | D8: =IF(OR(D6="",D7=""),"",D7/D6) -> 1.0661479 | E8: =IF(OR(E6="",E7=""),"",E7/E6) -> 1.0645161 | F8: =IF(OR(F6="",F7=""),"",F7/F6) -> 1.0677507 | G8: =IF(OR(G6="",G7=""),"",G7/G6) -> 1.0661479 | H8: =IF(OR(H6="",H7=""),"",H7/H6) -> 1.0632184 | I8: =IF(OR(I6="",I7=""),"",I7/I6) -> 1.0699088 | J8: =IF(OR(J6="",J7=""),"",J7/J6) -> 1.0617284 | K8: =IF(OR(K6="",K7=""),"",K7/K6) -> 1.0698413
A9: 80 | B9: Center | C9: 4.57 | D9: 4.1 | E9: 5.44 | F9: 5.89 | G9: 4.1 | H9: 5.55 | I9: 5.25 | J9: 5.17 | K9: 5.03
B10: CTDIw | C10: 4.77 | D10: 4.28 | E10: 5.67 | F10: 6.16 | G10: 4.28 | H10: 5.78 | I10: 5.49 | J10: 5.38 | K10: 5.26
B11: k | C11: =IF(OR(C9="",C10=""),"",C10/C9) -> 1.0437637 | D11: =IF(OR(D9="",D10=""),"",D10/D9) -> 1.0439024 | E11: =IF(OR(E9="",E10=""),"",E10/E9) -> 1.0422794 | F11: =IF(OR(F9="",F10=""),"",F10/F9) -> 1.0458404 | G11: =IF(OR(G9="",G10=""),"",G10/G9) -> 1.0439024 | H11: =IF(OR(H9="",H10=""),"",H10/H9) -> 1.0414414 | I11: =IF(OR(I9="",I10=""),"",I10/I9) -> 1.0457143 | J11: =IF(OR(J9="",J10=""),"",J10/J9) -> 1.040619 | K11: =IF(OR(K9="",K10=""),"",K10/K9) -> 1.0457256
A12: 100 | B12: Center | C12: 8.84 | D12: 7.93 | E12: 10.53 | F12: 11.4 | G12: 7.93 | H12: 10.73 | I12: 10.17 | J12: 10 | K12: 9.73
B13: CTDIw | C13: 9.02 | D13: 8.1 | E13: 10.7 | F13: 11.64 | G13: 8.1 | H13: 10.91 | I13: 10.39 | J13: 10.16 | K13: 9.94
B14: k | C14: =IF(OR(C12="",C13=""),"",C13/C12) -> 1.020362 | D14: =IF(OR(D12="",D13=""),"",D13/D12) -> 1.0214376 | E14: =IF(OR(E12="",E13=""),"",E13/E12) -> 1.0161443 | F14: =IF(OR(F12="",F13=""),"",F13/F12) -> 1.0210526 | G14: =IF(OR(G12="",G13=""),"",G13/G12) -> 1.0214376 | H14: =IF(OR(H12="",H13=""),"",H13/H12) -> 1.0167754 | I14: =IF(OR(I12="",I13=""),"",I13/I12) -> 1.0216323 | J14: =IF(OR(J12="",J13=""),"",J13/J12) -> 1.016 | K14: =IF(OR(K12="",K13=""),"",K13/K12) -> 1.0215827
A15: 120 | B15: Center | C15: 14.89 | D15: 13.36 | E15: 17.69 | F15: 19.21 | G15: 13.36 | H15: 18.03 | I15: 17.14 | J15: 16.8 | K15: 16.4
B16: CTDIw | C16: 15.07 | D16: 13.52 | E16: 17.84 | F16: 19.43 | G16: 13.52 | H16: 18.18 | I16: 17.34 | J16: 16.94 | K16: 16.59
B17: k | C17: =IF(OR(C15="",C16=""),"",C16/C15) -> 1.0120887 | D17: =IF(OR(D15="",D16=""),"",D16/D15) -> 1.011976 | E17: =IF(OR(E15="",E16=""),"",E16/E15) -> 1.0084794 | F17: =IF(OR(F15="",F16=""),"",F16/F15) -> 1.0114524 | G17: =IF(OR(G15="",G16=""),"",G16/G15) -> 1.011976 | H17: =IF(OR(H15="",H16=""),"",H16/H15) -> 1.0083195 | I17: =IF(OR(I15="",I16=""),"",I16/I15) -> 1.0116686 | J17: =IF(OR(J15="",J16=""),"",J16/J15) -> 1.0083333 | K17: =IF(OR(K15="",K16=""),"",K16/K15) -> 1.0115854
A18: 140 | B18: Center | C18: 21.22 | D18: 19.04 | E18: 25.23 | F18: 27.37 | G18: 19.04 | H18: 25.72 | I18: 24.42 | J18: 23.96 | K18: 23.37
B19: CTDIw | C19: 21.38 | D19: 19.18 | E19: 25.35 | F19: 27.57 | G19: 19.18 | H19: 25.83 | I19: 24.6 | J19: 24.07 | K19: 23.54
B20: k | C20: =IF(OR(C18="",C19=""),"",C19/C18) -> 1.0075401 | D20: =IF(OR(D18="",D19=""),"",D19/D18) -> 1.0073529 | E20: =IF(OR(E18="",E19=""),"",E19/E18) -> 1.0047562 | F20: =IF(OR(F18="",F19=""),"",F19/F18) -> 1.0073073 | G20: =IF(OR(G18="",G19=""),"",G19/G18) -> 1.0073529 | H20: =IF(OR(H18="",H19=""),"",H19/H18) -> 1.0042768 | I20: =IF(OR(I18="",I19=""),"",I19/I18) -> 1.007371 | J20: =IF(OR(J18="",J19=""),"",J19/J18) -> 1.004591 | K20: =IF(OR(K18="",K19=""),"",K19/K18) -> 1.0072743
